Workbook

Sheet 2026-01
A1: 苏州晶讯科技股份有限公司 品管部
A2: 序号 | B2: 姓名 | C2: 2026年1月出勤状况(工作日:21天) | AH2: 本月 累计年假 | AI2: 本月累计调休 | AJ2: 本月累计病假 | AK2: 本月累计事假 | AL2: 本月累计加班 | AO2: 年度 总计 年假 | AP2: 备注
C3: 1 | D3: 2 | E3: 3 | F3: 4 | G3: 5 | H3: 6 | I3: 7 | J3: 8 | K3: 9 | L3: 10 | M3: 11 | N3: 12 | O3: 13 | P3: 14 | Q3: 15 | R3: 16 | S3: 17 | T3: 18 | U3: 19 | V3: 20 | W3: 21 | X3: 22 | Y3: 23 | Z3: 24 | AA3: 25 | AB3: 26 | AC3: 27 | AD3: 28 | AE3: 29 | AF3: 30 | AG3: 31 | AL3: 平时 | AM3: 休息日 | AN3: 国假
C4: G | D4: S | E4: S | F4: P | G4: P | H4: P | I4: P | J4: P | K4: P | L4: S | M4: S | N4: P | O4: P | P4: P | Q4: P | R4: P | S4: S | T4: S | U4: P | V4: P | W4: P | X4: P | Y4: P | Z4: S | AA4: S | AB4: P | AC4: P | AD4: P | AE4: P | AF4: P | AG4: S
A5: 1 | B5: 马道旭 | AH5: =-(SUMIF(C5:AG5,"=年",C6:AG6)) -> 0 | AI5: =-(SUMIF(C5:AG5,"=调",C6:AG6)) -> 0 | AJ5: =-(SUMIF(C5:AG5,"=病",C6:AG6)) -> 0 | AK5: =-(SUMIF(C5:AG5,"=事",C6:AG6)) -> 0 | AL5: =SUMIF(C4:AG4,"P",C5:AG6) -> 0 | AM5: =SUMIF(C4:AG4,"S",C5:AG6) -> 0 | AN5: =SUMIF(C4:AG4,"G",C5:AG6) -> 0 | AO5: =AH5 -> 0
AL6: =IF(SUM(C5:AG5)-AI5=0,"√",SUM(C5:AG5)-AI5) -> √
A7: 2 | B7: 顾桢鸿 | AG7: 4 | AH7: =-(SUMIF(C7:AG7,"=年",C8:AG8)) -> 0 | AI7: =-(SUMIF(C7:AG7,"=调",C8:AG8)) -> 0 | AJ7: =-(SUMIF(C7:AG7,"=病",C8:AG8)) -> 0 | AK7: =-(SUMIF(C7:AG7,"=事",C8:AG8)) -> 0 | AL7: =SUMIF(C4:AG4,"P",C7:AG8) -> 0 | AM7: =SUMIF(C4:AG4,"S",C7:AG8) -> 4 | AN7: =SUMIF(C4:AG4,"G",C7:AG8) -> 0 | AO7: =AH7 -> 0
AL8: =IF(SUM(C7:AG7)-AI7=0,"√",SUM(C7:AG7)-AI7) -> 4
A9: 3 | B9: 顾晓维 | AH9: =-(SUMIF(C9:AG9,"=年",C10:AG10)) -> 0 | AI9: =-(SUMIF(C9:AG9,"=调",C10:AG10)) -> 0 | AJ9: =-(SUMIF(C9:AG9,"=病",C10:AG10)) -> 0 | AK9: =-(SUMIF(C9:AG9,"=事",C10:AG10)) -> 0 | AL9: =SUMIF(C4:AG4,"P",C9:AG10) -> 0 | AM9: =SUMIF(C4:AG4,"S",C9:AG10) -> 0 | AN9: =SUMIF(C4:AG4,"G",C9:AG10) -> 0 | AO9: =AH9 -> 0
AL10: =IF(SUM(C9:AG9)-AI9=0,"√",SUM(C9:AG9)-AI9) -> √
A11: 4 | B11: 吴丽娟 | C11: 7 | D11: 8.5 | E11: 8.5 | F11: 1 | H11: 3 | K11: 3 | L11: 8.5 | S11: 8.5 | T11: 8.5 | V11: 3 | Z11: 8.5 | AB11: 3 | AH11: =-(SUMIF(C11:AG11,"=年",C12:AG12)) -> 0 | AI11: =-(SUMIF(C11:AG11,"=调",C12:AG12)) -> 0 | AJ11: =-(SUMIF(C11:AG11,"=病",C12:AG12)) -> 0 | AK11: =-(SUMIF(C11:AG11,"=事",C12:AG12)) -> 0 | AL11: =SUMIF(C4:AG4,"P",C11:AG12) -> 13 | AM11: =SUMIF(C4:AG4,"S",C11:AG12) -> 51 | AN11: =SUMIF(C4:AG4,"G",C11:AG12) -> 7 | AO11: =AH11 -> 0
AL12: =IF(SUM(C11:AG11)-AI11=0,"√",SUM(C11:AG11)-AI11) -> 71
A13: 5 | B13: 夏莉萍 | D13: 8.5 | E13: 8.5 | H13: 年 | K13: 3 | L13: 8.5 | M13: 8.5 | S13: 8.5 | V13: 3 | W13: 调 | Z13: 8.5 | AA13: 8.5 | AB13: 3 | AF13: 调 | AG13: 8.5 | AH13: =-(SUMIF(C13:AG13,"=年",C14:AG14)) -> 8 | AI13: =-(SUMIF(C13:AG13,"=调",C14:AG14)) -> 6 | AJ13: =-(SUMIF(C13:AG13,"=病",C14:AG14)) -> 0 | AK13: =-(SUMIF(C13:AG13,"=事",C14:AG14)) -> 0 | AL13: =SUMIF(C4:AG4,"P",C13:AG14) -> 9 | AM13: =SUMIF(C4:AG4,"S",C13:AG14) -> 68 | AN13: =SUMIF(C4:AG4,"G",C13:AG14) -> 0 | AO13: =AH13 -> 8
H14: -8 | W14: -3 | AF14: -3 | AL14: =IF(SUM(C13:AG13)-AI13=0,"√",SUM(C13:AG13)-AI13) -> 71
A15: 6 | B15: 徐启双 | C15: 3 | D15: 8.5 | E15: 8.5 | H15: 3 | L15: 8.5 | M15: 8.5 | S15: 8.5 | T15: 8.5 | V15: 3 | X15: 3 | Z15: 8.5 | AB15: 3 | AG15: 8.5 | AH15: =-(SUMIF(C15:AG15,"=年",C16:AG16)) -> 0 | AI15: =-(SUMIF(C15:AG15,"=调",C16:AG16)) -> 0 | AJ15: =-(SUMIF(C15:AG15,"=病",C16:AG16)) -> 0 | AK15: =-(SUMIF(C15:AG15,"=事",C16:AG16)) -> 0 | AL15: =SUMIF(C4:AG4,"P",C15:AG16) -> 12 | AM15: =SUMIF(C4:AG4,"S",C15:AG16) -> 68 | AN15: =SUMIF(C4:AG4,"G",C15:AG16) -> 3 | AO15: =AH15 -> 0
AL16: =IF(SUM(C15:AG15)-AI15=0,"√",SUM(C15:AG15)-AI15) -> 83
A17: 7 | B17: 张静 | AH17: =-(SUMIF(C17:AG17,"=年",C18:AG18)) -> 0 | AI17: =-(SUMIF(C17:AG17,"=调",C18:AG18)) -> 0 | AJ17: =-(SUMIF(C17:AG17,"=病",C18:AG18)) -> 0 | AK17: =-(SUMIF(C17:AG17,"=事",C18:AG18)) -> 0 | AL17: =SUMIF(C4:AG4,"P",C17:AG18) -> 0 | AM17: =SUMIF(C4:AG4,"S",C17:AG18) -> 0 | AN17: =SUMIF(C4:AG4,"G",C17:AG18) -> 0 | AO17: =AH17 -> 0
AL18: =IF(SUM(C17:AG17)-AI17=0,"√",SUM(C17:AG17)-AI17) -> √
A19: 8 | B19: 尤文娟 | E19: 8.5 | M19: 8.5 | O19: 3 | Q19: 2 | S19: 8.5 | X19: 3 | AH19: =-(SUMIF(C19:AG19,"=年",C20:AG20)) -> 0 | AI19: =-(SUMIF(C19:AG19,"=调",C20:AG20)) -> 0 | AJ19: =-(SUMIF(C19:AG19,"=病",C20:AG20)) -> 0 | AK19: =-(SUMIF(C19:AG19,"=事",C20:AG20)) -> 0 | AL19: =SUMIF(C4:AG4,"P",C19:AG20) -> 8 | AM19: =SUMIF(C4:AG4,"S",C19:AG20) -> 25.5 | AN19: =SUMIF(C4:AG4,"G",C19:AG20) -> 0 | AO19: =AH19 -> 0
AL20: =IF(SUM(C19:AG19)-AI19=0,"√",SUM(C19:AG19)-AI19) -> 33.5
A21: 9 | B21: 夏卉 | D21: 8.5 | E21: 8.5 | H21: 3 | L21: 8.5 | M21: 8.5 | T21: 8.5 | V21: 3 | W21: 3 | Z21: 8.5 | AA21: 8.5 | AB21: 3 | AG21: 8.5 | AH21: =-(SUMIF(C21:AG21,"=年",C22:AG22)) -> 0 | AI21: =-(SUMIF(C21:AG21,"=调",C22:AG22)) -> 0 | AJ21: =-(SUMIF(C21:AG21,"=病",C22:AG22)) -> 0 | AK21: =-(SUMIF(C21:AG21,"=事",C22:AG22)) -> 0 | AL21: =SUMIF(C4:AG4,"P",C21:AG22) -> 12 | AM21: =SUMIF(C4:AG4,"S",C21:AG22) -> 68 | AN21: =SUMIF(C4:AG4,"G",C21:AG22) -> 0 | AO21: =AH21 -> 0
AL22: =IF(SUM(C21:AG21)-AI21=0,"√",SUM(C21:AG21)-AI21) -> 80
A23: 10 | B23: 惠雅 | D23: 8.5 | E23: 8.5 | H23: 3 | L23: 8.5 | M23: 8.5 | S23: 8.5 | T23: 8.5 | V23: 3 | W23: 3 | AA23: 8.5 | AB23: 3 | AG23: 8.5 | AH23: =-(SUMIF(C23:AG23,"=年",C24:AG24)) -> 0 | AI23: =-(SUMIF(C23:AG23,"=调",C24:AG24)) -> 0 | AJ23: =-(SUMIF(C23:AG23,"=病",C24:AG24)) -> 0 | AK23: =-(SUMIF(C23:AG23,"=事",C24:AG24)) -> 0 | AL23: =SUMIF(C4:AG4,"P",C23:AG24) -> 12 | AM23: =SUMIF(C4:AG4,"S",C23:AG24) -> 68 | AN23: =SUMIF(C4:AG4,"G",C23:AG24) -> 0 | AO23: =AH23 -> 0
AL24: =IF(SUM(C23:AG23)-AI23=0,"√",SUM(C23:AG23)-AI23) -> 80
A25: 11 | B25: 张永妹 | D25: 8.5 | E25: 8.5 | H25: 3 | L25: 8.5 | M25: 8.5 | S25: 8.5 | T25: 8.5 | V25: 3 | X25: 3 | Z25: 8.5 | AA25: 8.5 | AB25: 3 | AG25: 8.5 | AH25: =-(SUMIF(C25:AG25,"=年",C26:AG26)) -> 0 | AI25: =-(SUMIF(C25:AG25,"=调",C26:AG26)) -> 0 | AJ25: =-(SUMIF(C25:AG25,"=病",C26:AG26)) -> 0 | AK25: =-(SUMIF(C25:AG25,"=事",C26:AG26)) -> 0 | AL25: =SUMIF(C4:AG4,"P",C25:AG26) -> 12 | AM25: =SUMIF(C4:AG4,"S",C25:AG26) -> 76.5 | AN25: =SUMIF(C4:AG4,"G",C25:AG26) -> 0 | AO25: =AH25 -> 0
AL26: =IF(SUM(C25:AG25)-AI25=0,"√",SUM(C25:AG25)-AI25) -> 88.5
A27: 12 | B27: 亢亦宁 | H27: 调 | O27: 调 | X27: 调 | Y27: 1.5 | AF27: 调 | AH27: =-(SUMIF(C27:AG27,"=年",C28:AG28)) -> 0 | AI27: =-(SUMIF(C27:AG27,"=调",C28:AG28)) -> 6 | AJ27: =-(SUMIF(C27:AG27,"=病",C28:AG28)) -> 0 | AK27: =-(SUMIF(C27:AG27,"=事",C28:AG28)) -> 0 | AL27: =SUMIF(C4:AG4,"P",C27:AG28) -> 1.5 | AM27: =SUMIF(C4:AG4,"S",C27:AG28)-AI27 -> -6 | AN27: =SUMIF(C4:AG4,"G",C27:AG28) -> 0 | AO27: =AH27 -> 0
H28: -2 | O28: -1.5 | X28: -1 | AF28: -1.5 | AL28: =IF(SUM(C27:AG27)-AI27=0,"√",SUM(C27:AG27)-AI27) -> -4.5
A29: 注：①“年”指年假； ②“病”指有薪病假； ③“事”指事假； ④单位：小时； ⑤“居”指居家办公；⑥调休优先抵扣优先级：双休日>国假>平时加班，调休后统计加班累计；
A30: 制表：（顾桢鸿） | S30: 审核：（马道旭） | AJ30: 核准：

Sheet 2026-02
A1: 苏州晶讯科技股份有限公司 品管部
A2: 序号 | B2: 姓名 | C2: 2026年2月出勤状况(工作日:16天) | AH2: 本月 累计年假 | AI2: 本月累计调休 | AJ2: 本月累计病假 | AK2: 本月累计事假 | AL2: 本月累计加班 | AO2: 年度 总计 年假 | AP2: 备注
C3: 1 | D3: 2 | E3: 3 | F3: 4 | G3: 5 | H3: 6 | I3: 7 | J3: 8 | K3: 9 | L3: 10 | M3: 11 | N3: 12 | O3: 13 | P3: 14 | Q3: 15 | R3: 16 | S3: 17 | T3: 18 | U3: 19 | V3: 20 | W3: 21 | X3: 22 | Y3: 23 | Z3: 24 | AA3: 25 | AB3: 26 | AC3: 27 | AD3: 28 | AE3: 29 | AF3: 30 | AG3: 31 | AL3: 平时 | AM3: 休息日 | AN3: 国假
C4: S | D4: P | E4: P | F4: P | G4: P | H4: P | I4: S | J4: S | K4: P | L4: P | M4: P | N4: P | O4: P | P4: P | Q4: S | R4: G | S4: G | T4: G | U4: G | V4: S | W4: S | X4: S | Y4: S | Z4: P | AA4: P | AB4: P | AC4: P | AD4: P
A5: 1 | B5: 马道旭 | AH5: =-(SUMIF(C5:AG5,"=年",C6:AG6)) -> 0 | AI5: =-(SUMIF(C5:AG5,"=调",C6:AG6)) -> 0 | AJ5: =-(SUMIF(C5:AG5,"=病",C6:AG6)) -> 0 | AK5: =-(SUMIF(C5:AG5,"=事",C6:AG6)) -> 0 | AL5: =SUMIF(C4:AG4,"P",C5:AG6) -> 0 | AM5: =SUMIF(C4:AG4,"S",C5:AG6) -> 0 | AN5: =SUMIF(C4:AG4,"G",C5:AG6) -> 0 | AO5: =AH5+'2026-01'!AO5 -> 0
AL6: =IF(SUM(C5:AG5)-AI5=0,"√",SUM(C5:AG5)-AI5) -> √
A7: 2 | B7: 顾桢鸿 | F7: 年 | G7: 年 | H7: 年 | AA7: 年 | AD7: 年 | AH7: =-(SUMIF(C7:AG7,"=年",C8:AG8)) -> 36 | AI7: =-(SUMIF(C7:AG7,"=调",C8:AG8)) -> 0 | AJ7: =-(SUMIF(C7:AG7,"=病",C8:AG8)) -> 0 | AK7: =-(SUMIF(C7:AG7,"=事",C8:AG8)) -> 0 | AL7: =SUMIF(C4:AG4,"P",C7:AG8) -> 0 | AM7: =SUMIF(C4:AG4,"S",C7:AG8) -> 0 | AN7: =SUMIF(C4:AG4,"G",C7:AG8) -> 0 | AO7: =AH7+'2026-01'!AO7 -> 36
F8: -8 | G8: -8 | H8: -8 | AA8: -8 | AD8: -4 | AL8: =IF(SUM(C7:AG7)-AI7=0,"√",SUM(C7:AG7)-AI7) -> √
A9: 3 | B9: 顾晓维 | F9: 年 | G9: 年 | I9: 8.5 | AH9: =-(SUMIF(C9:AG9,"=年",C10:AG10)) -> 6 | AI9: =-(SUMIF(C9:AG9,"=调",C10:AG10)) -> 0 | AJ9: =-(SUMIF(C9:AG9,"=病",C10:AG10)) -> 0 | AK9: =-(SUMIF(C9:AG9,"=事",C10:AG10)) -> 0 | AL9: =SUMIF(C4:AG4,"P",C9:AG10) -> 0 | AM9: =SUMIF(C4:AG4,"S",C9:AG10) -> 8.5 | AN9: =SUMIF(C4:AG4,"G",C9:AG10) -> 0 | AO9: =AH9+'2026-01'!AO9 -> 6
F10: -3 | G10: -3 | AL10: =IF(SUM(C9:AG9)-AI9=0,"√",SUM(C9:AG9)-AI9) -> 8.5
A11: 4 | B11: 吴丽娟 | C11: 8.5 | I11: 8.5 | J11: 8.5 | P11: 8.5 | Q11: 8.5 | X11: 8.5 | Y11: 8.5 | AH11: =-(SUMIF(C11:AG11,"=年",C12:AG12)) -> 0 | AI11: =-(SUMIF(C11:AG11,"=调",C12:AG12)) -> 0 | AJ11: =-(SUMIF(C11:AG11,"=病",C12:AG12)) -> 0 | AK11: =-(SUMIF(C11:AG11,"=事",C12:AG12)) -> 0 | AL11: =SUMIF(C4:AG4,"P",C11:AG12) -> 8.5 | AM11: =SUMIF(C4:AG4,"S",C11:AG12) -> 51 | AN11: =SUMIF(C4:AG4,"G",C11:AG12) -> 0 | AO11: =AH11+'2026-01'!AO11 -> 0
AL12: =IF(SUM(C11:AG11)-AI11=0,"√",SUM(C11:AG11)-AI11) -> 59.5
A13: 5 | B13: 夏莉萍 | D13: 年 | I13: 8.5 | J13: 8.5 | K13: 年 | T13: 2 | V13: 8.5 | W13: 8.5 | X13: 8.5 | Y13: 8.5 | AH13: =-(SUMIF(C13:AG13,"=年",C14:AG14)) -> 10 | AI13: =-(SUMIF(C13:AG13,"=调",C14:AG14)) -> 0 | AJ13: =-(SUMIF(C13:AG13,"=病",C14:AG14)) -> 0 | AK13: =-(SUMIF(C13:AG13,"=事",C14:AG14)) -> 0 | AL13: =SUMIF(C4:AG4,"P",C13:AG14) -> 0 | AM13: =SUMIF(C4:AG4,"S",C13:AG14) -> 51 | AN13: =SUMIF(C4:AG4,"G",C13:AG14) -> 2 | AO13: =AH13+'2026-01'!AO13 -> 18
D14: -2 | K14: -8 | AL14: =IF(SUM(C13:AG13)-AI13=0,"√",SUM(C13:AG13)-AI13) -> 53
A15: 6 | B15: 徐启双 | C15: 8.5 | J15: 8.5 | Q15: 8.5 | W15: 8.5 | Y15: 8.5 | AH15: =-(SUMIF(C15:AG15,"=年",C16:AG16)) -> 0 | AI15: =-(SUMIF(C15:AG15,"=调",C16:AG16)) -> 0 | AJ15: =-(SUMIF(C15:AG15,"=病",C16:AG16)) -> 0 | AK15: =-(SUMIF(C15:AG15,"=事",C16:AG16)) -> 0 | AL15: =SUMIF(C4:AG4,"P",C15:AG16) -> 0 | AM15: =SUMIF(C4:AG4,"S",C15:AG16) -> 42.5 | AN15: =SUMIF(C4:AG4,"G",C15:AG16) -> 0 | AO15: =AH15+'2026-01'!AO15 -> 0
AL16: =IF(SUM(C15:AG15)-AI15=0,"√",SUM(C15:AG15)-AI15) -> 42.5
A17: 7 | B17: 张静 | J17: 8.5 | N17: 年 | O17: 年 | AH17: =-(SUMIF(C17:AG17,"=年",C18:AG18)) -> 9 | AI17: =-(SUMIF(C17:AG17,"=调",C18:AG18)) -> 0 | AJ17: =-(SUMIF(C17:AG17,"=病",C18:AG18)) -> 0 | AK17: =-(SUMIF(C17:AG17,"=事",C18:AG18)) -> 0 | AL17: =SUMIF(C4:AG4,"P",C17:AG18) -> 0 | AM17: =SUMIF(C4:AG4,"S",C17:AG18) -> 8.5 | AN17: =SUMIF(C4:AG4,"G",C17:AG18) -> 0 | AO17: =AH17+'2026-01'!AO17 -> 9
N18: -1 | O18: -8 | AL18: =IF(SUM(C17:AG17)-AI17=0,"√",SUM(C17:AG17)-AI17) -> 8.5
A19: 8 | B19: 尤文娟 | C19: 8.5 | I19: 8.5 | J19: 8.5 | V19: 8.5 | W19: 8.5 | X19: 8.5 | AH19: =-(SUMIF(C19:AG19,"=年",C20:AG20)) -> 0 | AI19: =-(SUMIF(C19:AG19,"=调",C20:AG20)) -> 0 | AJ19: =-(SUMIF(C19:AG19,"=病",C20:AG20)) -> 0 | AK19: =-(SUMIF(C19:AG19,"=事",C20:AG20)) -> 0 | AL19: =SUMIF(C4:AG4,"P",C19:AG20) -> 0 | AM19: =SUMIF(C4:AG4,"S",C19:AG20) -> 51 | AN19: =SUMIF(C4:AG4,"G",C19:AG20) -> 0 | AO19: =AH19+'2026-01'!AO19 -> 0
AL20: =IF(SUM(C19:AG19)-AI19=0,"√",SUM(C19:AG19)-AI19) -> 51
A21: 9 | B21: 夏卉 | C21: 10.5 | I21: 8.5 | M21: 年 | Q21: 8.5 | S21: 2 | W21: 8.5 | X21: 8.5 | Y21: 8.5 | AH21: =-(SUMIF(C21:AG21,"=年",C22:AG22)) -> 2 | AI21: =-(SUMIF(C21:AG21,"=调",C22:AG22)) -> 0 | AJ21: =-(SUMIF(C21:AG21,"=病",C22:AG22)) -> 0 | AK21: =-(SUMIF(C21:AG21,"=事",C22:AG22)) -> 0 | AL21: =SUMIF(C4:AG4,"P",C21:AG22) -> 0 | AM21: =SUMIF(C4:AG4,"S",C21:AG22) -> 53 | AN21: =SUMIF(C4:AG4,"G",C21:AG22) -> 2 | AO21: =AH21+'2026-01'!AO21 -> 2
M22: -2 | AL22: =IF(SUM(C21:AG21)-AI21=0,"√",SUM(C21:AG21)-AI21) -> 55
A23: 10 | B23: 惠雅 | J23: 8.5 | K23: 年 | P23: 8.5 | Q23: 8.5 | U23: 6 | V23: 8.5 | W23: 8.5 | X23: 8.5 | Y23: 8.5 | AH23: =-(SUMIF(C23:AG23,"=年",C24:AG24)) -> 1.5 | AI23: =-(SUMIF(C23:AG23,"=调",C24:AG24)) -> 0 | AJ23: =-(SUMIF(C23:AG23,"=病",C24:AG24)) -> 0 | AK23: =-(SUMIF(C23:AG23,"=事",C24:AG24)) -> 0 | AL23: =SUMIF(C4:AG4,"P",C23:AG24) -> 8.5 | AM23: =SUMIF(C4:AG4,"S",C23:AG24) -> 51 | AN23: =SUMIF(C4:AG4,"G",C23:AG24) -> 6 | AO23: =AH23+'2026-01'!AO23 -> 1.5
K24: -1.5 | AL24: =IF(SUM(C23:AG23)-AI23=0,"√",SUM(C23:AG23)-AI23) -> 65.5
A25: 11 | B25: 张永妹 | I25: 8.5 | R25: 6 | V25: 8.5 | W25: 8.5 | X25: 8.5 | Y25: 8.5 | AH25: =-(SUMIF(C25:AG25,"=年",C26:AG26)) -> 0 | AI25: =-(SUMIF(C25:AG25,"=调",C26:AG26)) -> 0 | AJ25: =-(SUMIF(C25:AG25,"=病",C26:AG26)) -> 0 | AK25: =-(SUMIF(C25:AG25,"=事",C26:AG26)) -> 0 | AL25: =SUMIF(C4:AG4,"P",C25:AG26) -> 0 | AM25: =SUMIF(C4:AG4,"S",C25:AG26) -> 42.5 | AN25: =SUMIF(C4:AG4,"G",C25:AG26) -> 6 | AO25: =AH25+'2026-01'!AO25 -> 0
AL26: =IF(SUM(C25:AG25)-AI25=0,"√",SUM(C25:AG25)-AI25) -> 48.5
A27: 12 | B27: 亢亦宁 | E27: 年 | M27: 调 | N27: 调 | O27: 调 | Z27: 年 | AA27: 年 | AB27: 年 | AC27: 年 | AD27: 年 | AH27: =-(SUMIF(C27:AG27,"=年",C28:AG28)) -> 43 | AI27: =-(SUMIF(C27:AG27,"=调",C28:AG28)) -> 18 | AJ27: =-(SUMIF(C27:AG27,"=病",C28:AG28)) -> 0 | AK27: =-(SUMIF(C27:AG27,"=事",C28:AG28)) -> 0 | AL27: =SUMIF(C4:AG4,"P",C27:AG28) -> 0 | AM27: =SUMIF(C4:AG4,"S",C27:AG28)-AI27 -> -18 | AN27: =SUMIF(C4:AG4,"G",C27:AG28) -> 0 | AO27: =AH27+'2026-01'!AO27 -> 43
E28: -3 | M28: -2 | N28: -8 | O28: -8 | Z28: -8 | AA28: -8 | AB28: -8 | AC28: -8 | AD28: -8 | AL28: =IF(SUM(C27:AG27)-AI27=0,"√",SUM(C27:AG27)-AI27) -> -18
A29: 注：①“年”指年假； ②“病”指有薪病假； ③“事”指事假； ④单位：小时； ⑤“居”指居家办公；⑥调休优先抵扣优先级：双休日>国假>平时加班，调休后统计加班累计；
A30: 制表：（顾桢鸿） | S30: 审核：（马道旭） | AJ30: 核准：

Sheet 2026-03
A1: 苏州晶讯科技股份有限公司 品管部
A2: 序号 | B2: 姓名 | C2: 2026年3月出勤状况(工作日:22天) | AH2: 本月累计 | AO2: 年度 总计 年假 | AP2: 备注
C3: 1 | D3: 2 | E3: 3 | F3: 4 | G3: 5 | H3: 6 | I3: 7 | J3: 8 | K3: 9 | L3: 10 | M3: 11 | N3: 12 | O3: 13 | P3: 14 | Q3: 15 | R3: 16 | S3: 17 | T3: 18 | U3: 19 | V3: 20 | W3: 21 | X3: 22 | Y3: 23 | Z3: 24 | AA3: 25 | AB3: 26 | AC3: 27 | AD3: 28 | AE3: 29 | AF3: 30 | AG3: 31 | AH3: 请假 | AL3: 加班
C4: S | D4: P | E4: P | F4: P | G4: P | H4: P | I4: S | J4: S | K4: P | L4: P | M4: P | N4: P | O4: P | P4: S | Q4: S | R4: P | S4: P | T4: P | U4: P | V4: P | W4: S | X4: S | Y4: P | Z4: P | AA4: P | AB4: P | AC4: P | AD4: S | AE4: S | AF4: P | AG4: P | AH4: 年假 | AI4: 调休 | AJ4: 病假 | AK4: 事假 | AL4: 平时 | AM4: 休息日 | AN4: 国假
A5: 1 | B5: 马道旭 | K5: 年 | AH5: =-(SUMIF(C5:AG5,"=年",C6:AG6)) -> 8 | AI5: =-(SUMIF(C5:AG5,"=调",C6:AG6)) -> 0 | AJ5: =-(SUMIF(C5:AG5,"=病",C6:AG6)) -> 0 | AK5: =-(SUMIF(C5:AG5,"=事",C6:AG6)) -> 0 | AL5: =SUMIF(C4:AG4,"P",C5:AG6) -> 0 | AM5: =SUMIF(C4:AG4,"S",C5:AG6) -> 0 | AN5: =SUMIF(C4:AG4,"G",C5:AG6) -> 0 | AO5: =AH5+'2026-02'!AO5 -> 8
K6: -8 | AL6: =IF(SUM(C5:AG5)-AI5=0,"√",SUM(C5:AG5)-AI5) -> √
A7: 2 | B7: 顾桢鸿 | I7: 8.5 | AH7: =-(SUMIF(C7:AG7,"=年",C8:AG8)) -> 0 | AI7: =-(SUMIF(C7:AG7,"=调",C8:AG8)) -> 0 | AJ7: =-(SUMIF(C7:AG7,"=病",C8:AG8)) -> 0 | AK7: =-(SUMIF(C7:AG7,"=事",C8:AG8)) -> 0 | AL7: =SUMIF(C4:AG4,"P",C7:AG8) -> 0 | AM7: =SUMIF(C4:AG4,"S",C7:AG8) -> 8.5 | AN7: =SUMIF(C4:AG4,"G",C7:AG8) -> 0 | AO7: =AH7+'2026-02'!AO7 -> 36
AL8: =IF(SUM(C7:AG7)-AI7=0,"√",SUM(C7:AG7)-AI7) -> 8.5
A9: 3 | B9: 顾晓维 | P9: 3 | AH9: =-(SUMIF(C9:AG9,"=年",C10:AG10)) -> 0 | AI9: =-(SUMIF(C9:AG9,"=调",C10:AG10)) -> 0 | AJ9: =-(SUMIF(C9:AG9,"=病",C10:AG10)) -> 0 | AK9: =-(SUMIF(C9:AG9,"=事",C10:AG10)) -> 0 | AL9: =SUMIF(C4:AG4,"P",C9:AG10) -> 0 | AM9: =SUMIF(C4:AG4,"S",C9:AG10) -> 3 | AN9: =SUMIF(C4:AG4,"G",C9:AG10) -> 0 | AO9: =AH9+'2026-02'!AO9 -> 6
AL10: =IF(SUM(C9:AG9)-AI9=0,"√",SUM(C9:AG9)-AI9) -> 3
A11: 4 | B11: 吴丽娟 | C11: 8.5 | H11: 3 | I11: 8.5 | P11: 8.5 | Q11: 8.5 | U11: 3 | V11: 3 | X11: 8.5 | AD11: 8.5 | AE11: 8.5 | AH11: =-(SUMIF(C11:AG11,"=年",C12:AG12)) -> 0 | AI11: =-(SUMIF(C11:AG11,"=调",C12:AG12)) -> 0 | AJ11: =-(SUMIF(C11:AG11,"=病",C12:AG12)) -> 0 | AK11: =-(SUMIF(C11:AG11,"=事",C12:AG12)) -> 0 | AL11: =SUMIF(C4:AG4,"P",C11:AG12) -> 9 | AM11: =SUMIF(C4:AG4,"S",C11:AG12) -> 59.5 | AN11: =SUMIF(C4:AG4,"G",C11:AG12) -> 0 | AO11: =AH11+'2026-02'!AO11 -> 0
AL12: =IF(SUM(C11:AG11)-AI11=0,"√",SUM(C11:AG11)-AI11) -> 68.5
A13: 5 | B13: 夏莉萍 | C13: 8.5 | H13: 3 | I13: 8.5 | P13: 8.5 | Q13: 8.5 | U13: 调 | V13: 调 | AD13: 8.5 | AE13: 8.5 | AH13: =-(SUMIF(C13:AG13,"=年",C14:AG14)) -> 0 | AI13: =-(SUMIF(C13:AG13,"=调",C14:AG14)) -> 16 | AJ13: =-(SUMIF(C13:AG13,"=病",C14:AG14)) -> 0 | AK13: =-(SUMIF(C13:AG13,"=事",C14:AG14)) -> 0 | AL13: =SUMIF(C4:AG4,"P",C13:AG14) -> 3 | AM13: =SUMIF(C4:AG4,"S",C13:AG14) -> 51 | AN13: =SUMIF(C4:AG4,"G",C13:AG14) -> 0 | AO13: =AH13+'2026-02'!AO13 -> 18
U14: -8 | V14: -8 | AL14: =IF(SUM(C13:AG13)-AI13=0,"√",SUM(C13:AG13)-AI13) -> 38
A15: 6 | B15: 徐启双 | C15: 8.5 | G15: 年 | H15: 3 | I15: 8.5 | J15: 8.5 | M15: 3 | O15: 3 | P15: 8.5 | Q15: 8.5 | V15: 3 | W15: 8.5 | X15: 8.5 | AD15: 8.5 | AH15: =-(SUMIF(C15:AG15,"=年",C16:AG16)) -> 8 | AI15: =-(SUMIF(C15:AG15,"=调",C16:AG16)) -> 0 | AJ15: =-(SUMIF(C15:AG15,"=病",C16:AG16)) -> 0 | AK15: =-(SUMIF(C15:AG15,"=事",C16:AG16)) -> 0 | AL15: =SUMIF(C4:AG4,"P",C15:AG16) -> 12 | AM15: =SUMIF(C4:AG4,"S",C15:AG16) -> 68 | AN15: =SUMIF(C4:AG4,"G",C15:AG16) -> 0 | AO15: =AH15+'2026-02'!AO15 -> 8
G16: -8 | AL16: =IF(SUM(C15:AG15)-AI15=0,"√",SUM(C15:AG15)-AI15) -> 80
A17: 7 | B17: 张静 | AH17: =-(SUMIF(C17:AG17,"=年",C18:AG18)) -> 0 | AI17: =-(SUMIF(C17:AG17,"=调",C18:AG18)) -> 0 | AJ17: =-(SUMIF(C17:AG17,"=病",C18:AG18)) -> 0 | AK17: =-(SUMIF(C17:AG17,"=事",C18:AG18)) -> 0 | AL17: =SUMIF(C4:AG4,"P",C17:AG18) -> 0 | AM17: =SUMIF(C4:AG4,"S",C17:AG18) -> 0 | AN17: =SUMIF(C4:AG4,"G",C17:AG18) -> 0 | AO17: =AH17+'2026-02'!AO17 -> 9
AL18: =IF(SUM(C17:AG17)-AI17=0,"√",SUM(C17:AG17)-AI17) -> √
A19: 8 | B19: 尤文娟 | C19: 8.5 | I19: 8.5 | J19: 8.5 | P19: =8.5+3 -> 11.5 | U19: 3 | V19: 3 | X19: 8.5 | AD19: 8.5 | AH19: =-(SUMIF(C19:AG19,"=年",C20:AG20)) -> 0 | AI19: =-(SUMIF(C19:AG19,"=调",C20:AG20)) -> 0 | AJ19: =-(SUMIF(C19:AG19,"=病",C20:AG20)) -> 0 | AK19: =-(SUMIF(C19:AG19,"=事",C20:AG20)) -> 0 | AL19: =SUMIF(C4:AG4,"P",C19:AG20) -> 6 | AM19: =SUMIF(C4:AG4,"S",C19:AG20) -> 54 | AN19: =SUMIF(C4:AG4,"G",C19:AG20) -> 0 | AO19: =AH19+'2026-02'!AO19 -> 0
AL20: =IF(SUM(C19:AG19)-AI19=0,"√",SUM(C19:AG19)-AI19) -> 60
A21: 9 | B21: 夏卉 | H21: 3 | I21: 8.5 | J21: 8.5 | P21: 8.5 | Q21: 8.5 | U21: 3 | V21: 3 | W21: 8.5 | AD21: 8.5 | AE21: 8.5 | AH21: =-(SUMIF(C21:AG21,"=年",C22:AG22)) -> 0 | AI21: =-(SUMIF(C21:AG21,"=调",C22:AG22)) -> 0 | AJ21: =-(SUMIF(C21:AG21,"=病",C22:AG22)) -> 0 | AK21: =-(SUMIF(C21:AG21,"=事",C22:AG22)) -> 0 | AL21: =SUMIF(C4:AG4,"P",C21:AG22) -> 9 | AM21: =SUMIF(C4:AG4,"S",C21:AG22) -> 59.5 | AN21: =SUMIF(C4:AG4,"G",C21:AG22) -> 0 | AO21: =AH21+'2026-02'!AO21 -> 2
AL22: =IF(SUM(C21:AG21)-AI21=0,"√",SUM(C21:AG21)-AI21) -> 68.5
A23: 10 | B23: 惠雅 | H23: 3 | J23: 8.5 | Q23: 8.5 | U23: 3 | V23: 3 | W23: 8.5 | X23: 8.5 | AD23: 8.5 | AE23: 8.5 | AH23: =-(SUMIF(C23:AG23,"=年",C24:AG24)) -> 0 | AI23: =-(SUMIF(C23:AG23,"=调",C24:AG24)) -> 0 | AJ23: =-(SUMIF(C23:AG23,"=病",C24:AG24)) -> 0 | AK23: =-(SUMIF(C23:AG23,"=事",C24:AG24)) -> 0 | AL23: =SUMIF(C4:AG4,"P",C23:AG24) -> 9 | AM23: =SUMIF(C4:AG4,"S",C23:AG24) -> 51 | AN23: =SUMIF(C4:AG4,"G",C23:AG24) -> 0 | AO23: =AH23+'2026-02'!AO23 -> 1.5
AL24: =IF(SUM(C23:AG23)-AI23=0,"√",SUM(C23:AG23)-AI23) -> 60
A25: 11 | B25: 张永妹 | C25: 8.5 | H25: 3 | J25: 8.5 | P25: 8.5 | S25: 年 | T25: 年 | U25: 年 | V25: 年 | W25: 8.5 | X25: 8.5 | AE25: 8.5 | AH25: =-(SUMIF(C25:AG25,"=年",C26:AG26)) -> 32 | AI25: =-(SUMIF(C25:AG25,"=调",C26:AG26)) -> 0 | AJ25: =-(SUMIF(C25:AG25,"=病",C26:AG26)) -> 0 | AK25: =-(SUMIF(C25:AG25,"=事",C26:AG26)) -> 0 | AL25: =SUMIF(C4:AG4,"P",C25:AG26) -> 3 | AM25: =SUMIF(C4:AG4,"S",C25:AG26) -> 51 | AN25: =SUMIF(C4:AG4,"G",C25:AG26) -> 0 | AO25: =AH25+'2026-02'!AO25 -> 32
S26: -8 | T26: -8 | U26: -8 | V26: -8 | AL26: =IF(SUM(C25:AG25)-AI25=0,"√",SUM(C25:AG25)-AI25) -> 54
A27: 12 | B27: 亢亦宁 | L27: 1.5 | AH27: =-(SUMIF(C27:AG27,"=年",C28:AG28)) -> 0 | AI27: =-(SUMIF(C27:AG27,"=调",C28:AG28)) -> 0 | AJ27: =-(SUMIF(C27:AG27,"=病",C28:AG28)) -> 0 | AK27: =-(SUMIF(C27:AG27,"=事",C28:AG28)) -> 0 | AL27: =SUMIF(C4:AG4,"P",C27:AG28) -> 1.5 | AM27: =SUMIF(C4:AG4,"S",C27:AG28)-AI27 -> 0 | AN27: =SUMIF(C4:AG4,"G",C27:AG28) -> 0 | AO27: =AH27+'2026-02'!AO27 -> 43
AL28: =IF(SUM(C27:AG27)-AI27=0,"√",SUM(C27:AG27)-AI27) -> 1.5
A29: 注：①“年”指年假； ②“病”指有薪病假； ③“事”指事假； ④单位：小时； ⑤“居”指居家办公；⑥调休优先抵扣优先级：双休日>国假>平时加班，调休后统计加班累计；
A30: 制表：（顾桢鸿） | S30: 审核：（马道旭） | AJ30: 核准：

Sheet 2026-04
A1: 苏州晶讯科技股份有限公司 品管部
A2: 序号 | B2: 姓名 | C2: 2026年4月出勤状况(工作日:22天) | AH2: 本月累计 | AO2: 年度 总计 年假 | AP2: 备注
C3: 1 | D3: 2 | E3: 3 | F3: 4 | G3: 5 | H3: 6 | I3: 7 | J3: 8 | K3: 9 | L3: 10 | M3: 11 | N3: 12 | O3: 13 | P3: 14 | Q3: 15 | R3: 16 | S3: 17 | T3: 18 | U3: 19 | V3: 20 | W3: 21 | X3: 22 | Y3: 23 | Z3: 24 | AA3: 25 | AB3: 26 | AC3: 27 | AD3: 28 | AE3: 29 | AF3: 30 | AG3: 31 | AH3: 请假 | AL3: 加班
C4: P | D4: P | E4: P | F4: S | G4: G | H4: S | I4: P | J4: P | K4: P | L4: P | M4: S | N4: S | O4: P | P4: P | Q4: P | R4: P | S4: P | T4: S | U4: S | V4: P | W4: P | X4: P | Y4: P | Z4: P | AA4: S | AB4: S | AC4: P | AD4: P | AE4: P | AF4: P | AH4: 年假 | AI4: 调休 | AJ4: 病假 | AK4: 事假 | AL4: 平时 | AM4: 休息日 | AN4: 国假
A5: 1 | B5: 马道旭 | C5: 年 | R5: 年 | AH5: =-(SUMIF(C5:AG5,"=年",C6:AG6)) -> 12 | AI5: =-(SUMIF(C5:AG5,"=调",C6:AG6)) -> 0 | AJ5: =-(SUMIF(C5:AG5,"=病",C6:AG6)) -> 0 | AK5: =-(SUMIF(C5:AG5,"=事",C6:AG6)) -> 0 | AL5: =SUMIF(C4:AG4,"P",C5:AG6) -> 0 | AM5: =SUMIF(C4:AG4,"S",C5:AG6) -> 0 | AN5: =SUMIF(C4:AG4,"G",C5:AG6) -> 0 | AO5: =AH5+'2026-03'!AO5 -> 20
C6: -4 | R6: -8 | AL6: =IF(SUM(C5:AG5)-AI5=0,"√",SUM(C5:AG5)-AI5) -> √
A7: 2 | B7: 顾桢鸿 | O7: 调 | X7: 调 | AH7: =-(SUMIF(C7:AG7,"=年",C8:AG8)) -> 0 | AI7: =-(SUMIF(C7:AG7,"=调",C8:AG8)) -> 6 | AJ7: =-(SUMIF(C7:AG7,"=病",C8:AG8)) -> 0 | AK7: =-(SUMIF(C7:AG7,"=事",C8:AG8)) -> 0 | AL7: =SUMIF(C4:AG4,"P",C7:AG8) -> 0 | AM7: =SUMIF(C4:AG4,"S",C7:AG8) -> 0 | AN7: =SUMIF(C4:AG4,"G",C7:AG8) -> 0 | AO7: =AH7+'2026-03'!AO7 -> 36
O8: -2 | X8: -4 | AL8: =IF(SUM(C7:AG7)-AI7=0,"√",SUM(C7:AG7)-AI7) -> -6
A9: 3 | B9: 顾晓维 | D9: 3 | X9: 年 | Y9: 年 | Z9: 年 | AH9: =-(SUMIF(C9:AG9,"=年",C10:AG10)) -> 24 | AI9: =-(SUMIF(C9:AG9,"=调",C10:AG10)) -> 0 | AJ9: =-(SUMIF(C9:AG9,"=病",C10:AG10)) -> 0 | AK9: =-(SUMIF(C9:AG9,"=事",C10:AG10)) -> 0 | AL9: =SUMIF(C4:AG4,"P",C9:AG10) -> 3 | AM9: =SUMIF(C4:AG4,"S",C9:AG10) -> 0 | AN9: =SUMIF(C4:AG4,"G",C9:AG10) -> 0 | AO9: =AH9+'2026-03'!AO9 -> 30
X10: -8 | Y10: -8 | Z10: -8 | AL10: =IF(SUM(C9:AG9)-AI9=0,"√",SUM(C9:AG9)-AI9) -> 3
A11: 4 | B11: 吴丽娟 | F11: 8.5 | H11: 8.5 | J11: 3 | L11: 3 | M11: 8.5 | N11: 8.5 | T11: 8.5 | U11: 8.5 | V11: 调 | Z11: 3 | AA11: 8.5 | AB11: 8.5 | AH11: =-(SUMIF(C11:AG11,"=年",C12:AG12)) -> 0 | AI11: =-(SUMIF(C11:AG11,"=调",C12:AG12)) -> 2.5 | AJ11: =-(SUMIF(C11:AG11,"=病",C12:AG12)) -> 0 | AK11: =-(SUMIF(C11:AG11,"=事",C12:AG12)) -> 0 | AL11: =SUMIF(C4:AG4,"P",C11:AG12) -> 9 | AM11: =SUMIF(C4:AG4,"S",C11:AG12) -> 68 | AN11: =SUMIF(C4:AG4,"G",C11:AG12) -> 0 | AO11: =AH11+'2026-03'!AO11 -> 0
V12: -2.5 | AL12: =IF(SUM(C11:AG11)-AI11=0,"√",SUM(C11:AG11)-AI11) -> 74.5
A13: 5 | B13: 夏莉萍 | C13: 调 | F13: 8.5 | H13: 8.5 | J13: 3 | M13: 8.5 | N13: 8.5 | P13: 调 | T13: 8.5 | U13: 8.5 | Z13: 3 | AA13: 8.5 | AB13: 8.5 | AH13: =-(SUMIF(C13:AG13,"=年",C14:AG14)) -> 0 | AI13: =-(SUMIF(C13:AG13,"=调",C14:AG14)) -> 11 | AJ13: =-(SUMIF(C13:AG13,"=病",C14:AG14)) -> 0 | AK13: =-(SUMIF(C13:AG13,"=事",C14:AG14)) -> 0 | AL13: =SUMIF(C4:AG4,"P",C13:AG14) -> 6 | AM13: =SUMIF(C4:AG4,"S",C13:AG14) -> 68 | AN13: =SUMIF(C4:AG4,"G",C13:AG14) -> 0 | AO13: =AH13+'2026-03'!AO13 -> 18
C14: -3 | P14: -8 | AL14: =IF(SUM(C13:AG13)-AI13=0,"√",SUM(C13:AG13)-AI13) -> 63
A15: 6 | B15: 徐启双 | C15: 3 | F15: 8.5 | H15: 8.5 | K15: 3 | M15: 8.5 | N15: 8.5 | R15: 3 | T15: 8.5 | U15: 8.5 | Z15: 3 | AA15: 11.5 | AB15: 8.5 | AH15: =-(SUMIF(C15:AG15,"=年",C16:AG16)) -> 0 | AI15: =-(SUMIF(C15:AG15,"=调",C16:AG16)) -> 0 | AJ15: =-(SUMIF(C15:AG15,"=病",C16:AG16)) -> 0 | AK15: =-(SUMIF(C15:AG15,"=事",C16:AG16)) -> 0 | AL15: =SUMIF(C4:AG4,"P",C15:AG16) -> 12 | AM15: =SUMIF(C4:AG4,"S",C15:AG16) -> 71 | AN15: =SUMIF(C4:AG4,"G",C15:AG16) -> 0 | AO15: =AH15+'2026-03'!AO15 -> 8
AL16: =IF(SUM(C15:AG15)-AI15=0,"√",SUM(C15:AG15)-AI15) -> 83
A17: 7 | B17: 张静 | AF17: 年 | AH17: =-(SUMIF(C17:AG17,"=年",C18:AG18)) -> 4 | AI17: =-(SUMIF(C17:AG17,"=调",C18:AG18)) -> 0 | AJ17: =-(SUMIF(C17:AG17,"=病",C18:AG18)) -> 0 | AK17: =-(SUMIF(C17:AG17,"=事",C18:AG18)) -> 0 | AL17: =SUMIF(C4:AG4,"P",C17:AG18) -> 0 | AM17: =SUMIF(C4:AG4,"S",C17:AG18) -> 0 | AN17: =SUMIF(C4:AG4,"G",C17:AG18) -> 0 | AO17: =AH17+'2026-03'!AO17 -> 13
AF18: -4 | AL18: =IF(SUM(C17:AG17)-AI17=0,"√",SUM(C17:AG17)-AI17) -> √
A19: 8 | B19: 尤文娟 | F19: 8.5 | H19: 8.5 | K19: 3 | M19: 8.5 | N19: 8.5 | T19: 8.5 | Y19: 3 | AA19: 8.5 | AB19: 8.5 | AH19: =-(SUMIF(C19:AG19,"=年",C20:AG20)) -> 0 | AI19: =-(SUMIF(C19:AG19,"=调",C20:AG20)) -> 0 | AJ19: =-(SUMIF(C19:AG19,"=病",C20:AG20)) -> 0 | AK19: =-(SUMIF(C19:AG19,"=事",C20:AG20)) -> 0 | AL19: =SUMIF(C4:AG4,"P",C19:AG20) -> 6 | AM19: =SUMIF(C4:AG4,"S",C19:AG20) -> 59.5 | AN19: =SUMIF(C4:AG4,"G",C19:AG20) -> 0 | AO19: =AH19+'2026-03'!AO19 -> 0
AL20: =IF(SUM(C19:AG19)-AI19=0,"√",SUM(C19:AG19)-AI19) -> 65.5
A21: 9 | B21: 夏卉 | D21: 3 | F21: 8.5 | G21: 3 | H21: 8.5 | L21: 3 | M21: 8.5 | N21: 8.5 | T21: 8.5 | U21: 8.5 | Z21: 3 | AA21: 8.5 | AB21: 8.5 | AH21: =-(SUMIF(C21:AG21,"=年",C22:AG22)) -> 0 | AI21: =-(SUMIF(C21:AG21,"=调",C22:AG22)) -> 0 | AJ21: =-(SUMIF(C21:AG21,"=病",C22:AG22)) -> 0 | AK21: =-(SUMIF(C21:AG21,"=事",C22:AG22)) -> 0 | AL21: =SUMIF(C4:AG4,"P",C21:AG22) -> 9 | AM21: =SUMIF(C4:AG4,"S",C21:AG22) -> 68 | AN21: =SUMIF(C4:AG4,"G",C21:AG22) -> 3 | AO21: =AH21+'2026-03'!AO21 -> 2
AL22: =IF(SUM(C21:AG21)-AI21=0,"√",SUM(C21:AG21)-AI21) -> 80
A23: 10 | B23: 惠雅 | D23: 3 | F23: 8.5 | H23: 8.5 | M23: 8.5 | N23: 8.5 | P23: 年 | T23: 8.5 | U23: 8.5 | Z23: 3 | AA23: 8.5 | AB23: 8.5 | AH23: =-(SUMIF(C23:AG23,"=年",C24:AG24)) -> 1.5 | AI23: =-(SUMIF(C23:AG23,"=调",C24:AG24)) -> 0 | AJ23: =-(SUMIF(C23:AG23,"=病",C24:AG24)) -> 0 | AK23: =-(SUMIF(C23:AG23,"=事",C24:AG24)) -> 0 | AL23: =SUMIF(C4:AG4,"P",C23:AG24) -> 6 | AM23: =SUMIF(C4:AG4,"S",C23:AG24) -> 68 | AN23: =SUMIF(C4:AG4,"G",C23:AG24) -> 0 | AO23: =AH23+'2026-03'!AO23 -> 3
P24: -1.5 | AL24: =IF(SUM(C23:AG23)-AI23=0,"√",SUM(C23:AG23)-AI23) -> 74
A25: 11 | B25: 张永妹 | D25: 3 | F25: 8.5 | H25: 8.5 | K25: 3 | M25: 8.5 | N25: 8.5 | T25: 8.5 | U25: 8.5 | Z25: 3 | AA25: 8.5 | AB25: 8.5 | AH25: =-(SUMIF(C25:AG25,"=年",C26:AG26)) -> 0 | AI25: =-(SUMIF(C25:AG25,"=调",C26:AG26)) -> 0 | AJ25: =-(SUMIF(C25:AG25,"=病",C26:AG26)) -> 0 | AK25: =-(SUMIF(C25:AG25,"=事",C26:AG26)) -> 0 | AL25: =SUMIF(C4:AG4,"P",C25:AG26) -> 9 | AM25: =SUMIF(C4:AG4,"S",C25:AG26) -> 68 | AN25: =SUMIF(C4:AG4,"G",C25:AG26) -> 0 | AO25: =AH25+'2026-03'!AO25 -> 32
AL26: =IF(SUM(C25:AG25)-AI25=0,"√",SUM(C25:AG25)-AI25) -> 77
A27: 12 | B27: 亢亦宁 | AH27: =-(SUMIF(C27:AG27,"=年",C28:AG28)) -> 0 | AI27: =-(SUMIF(C27:AG27,"=调",C28:AG28)) -> 0 | AJ27: =-(SUMIF(C27:AG27,"=病",C28:AG28)) -> 0 | AK27: =-(SUMIF(C27:AG27,"=事",C28:AG28)) -> 0 | AL27: =SUMIF(C4:AG4,"P",C27:AG28) -> 0 | AM27: =SUMIF(C4:AG4,"S",C27:AG28)-AI27 -> 0 | AN27: =SUMIF(C4:AG4,"G",C27:AG28) -> 0 | AO27: =AH27+'2026-03'!AO27 -> 43
AL28: =IF(SUM(C27:AG27)-AI27=0,"√",SUM(C27:AG27)-AI27) -> √
A29: 注：①“年”指年假； ②“病”指有薪病假； ③“事”指事假； ④单位：小时； ⑤“居”指居家办公；⑥调休优先抵扣优先级：双休日>国假>平时加班，调休后统计加班累计；
A30: 制表：（顾桢鸿） | S30: 审核：（马道旭） | AJ30: 核准：

Sheet 2026-05
A1: 苏州晶讯科技股份有限公司 品管部
A2: 序号 | B2: 姓名 | C2: 2026年5月出勤状况(工作日:19天) | AH2: 本月累计 | AO2: 年度 总计 年假 | AP2: 备注
C3: 1 | D3: 2 | E3: 3 | F3: 4 | G3: 5 | H3: 6 | I3: 7 | J3: 8 | K3: 9 | L3: 10 | M3: 11 | N3: 12 | O3: 13 | P3: 14 | Q3: 15 | R3: 16 | S3: 17 | T3: 18 | U3: 19 | V3: 20 | W3: 21 | X3: 22 | Y3: 23 | Z3: 24 | AA3: 25 | AB3: 26 | AC3: 27 | AD3: 28 | AE3: 29 | AF3: 30 | AG3: 31 | AH3: 请假 | AL3: 加班
C4: G | D4: G | E4: G | F4: S | G4: S | H4: P | I4: P | J4: P | K4: P | L4: S | M4: P | N4: P | O4: P | P4: P | Q4: P | R4: S | S4: S | T4: P | U4: P | V4: P | W4: P | X4: P | Y4: S | Z4: S | AA4: P | AB4: P | AC4: P | AD4: P | AE4: P | AF4: S | AG4: S | AH4: 年假 | AI4: 调休 | AJ4: 病假 | AK4: 事假 | AL4: 平时 | AM4: 休息日 | AN4: 国假
A5: 1 | B5: 马道旭 | H5: 年 | W5: 年 | AH5: =-(SUMIF(C5:AG5,"=年",C6:AG6)) -> 8 | AI5: =-(SUMIF(C5:AG5,"=调",C6:AG6)) -> 0 | AJ5: =-(SUMIF(C5:AG5,"=病",C6:AG6)) -> 0 | AK5: =-(SUMIF(C5:AG5,"=事",C6:AG6)) -> 0 | AL5: =SUMIF(C4:AG4,"P",C5:AG6) -> 0 | AM5: =SUMIF(C4:AG4,"S",C5:AG6) -> 0 | AN5: =SUMIF(C4:AG4,"G",C5:AG6) -> 0 | AO5: =AH5+'2026-04'!AO5 -> 28
H6: -4 | W6: -4 | AL6: =IF(SUM(C5:AG5)-AI5=0,"√",SUM(C5:AG5)-AI5) -> √
A7: 2 | B7: 顾桢鸿 | J7: 调 | AH7: =-(SUMIF(C7:AG7,"=年",C8:AG8)) -> 0 | AI7: =-(SUMIF(C7:AG7,"=调",C8:AG8)) -> 3 | AJ7: =-(SUMIF(C7:AG7,"=病",C8:AG8)) -> 0 | AK7: =-(SUMIF(C7:AG7,"=事",C8:AG8)) -> 0 | AL7: =SUMIF(C4:AG4,"P",C7:AG8) -> 0 | AM7: =SUMIF(C4:AG4,"S",C7:AG8) -> 0 | AN7: =SUMIF(C4:AG4,"G",C7:AG8) -> 0 | AO7: =AH7+'2026-04'!AO7 -> 36
J8: -3 | AL8: =IF(SUM(C7:AG7)-AI7=0,"√",SUM(C7:AG7)-AI7) -> -3
A9: 3 | B9: 顾晓维 | X9: 年 | AF9: 8.5 | AG9: 8.5 | AH9: =-(SUMIF(C9:AG9,"=年",C10:AG10)) -> 4 | AI9: =-(SUMIF(C9:AG9,"=调",C10:AG10)) -> 0 | AJ9: =-(SUMIF(C9:AG9,"=病",C10:AG10)) -> 0 | AK9: =-(SUMIF(C9:AG9,"=事",C10:AG10)) -> 0 | AL9: =SUMIF(C4:AG4,"P",C9:AG10) -> 0 | AM9: =SUMIF(C4:AG4,"S",C9:AG10) -> 17 | AN9: =SUMIF(C4:AG4,"G",C9:AG10) -> 0 | AO9: =AH9+'2026-04'!AO9 -> 34
X10: -4 | AL10: =IF(SUM(C9:AG9)-AI9=0,"√",SUM(C9:AG9)-AI9) -> 17
A11: 4 | B11: 吴丽娟 | F11: 8.5 | G11: 8.5 | L11: 8.5 | M11: 3 | N11: 3 | O11: 3 | R11: 8.5 | S11: 8.5 | T11: 3 | V11: 3 | W11: 3 | Y11: 8.5 | Z11: 8.5 | AD11: 3 | AF11: 8.5 | AG11: 8.5 | AH11: =-(SUMIF(C11:AG11,"=年",C12:AG12)) -> 0 | AI11: =-(SUMIF(C11:AG11,"=调",C12:AG12)) -> 0 | AJ11: =-(SUMIF(C11:AG11,"=病",C12:AG12)) -> 0 | AK11: =-(SUMIF(C11:AG11,"=事",C12:AG12)) -> 0 | AL11: =SUMIF(C4:AG4,"P",C11:AG12) -> 21 | AM11: =SUMIF(C4:AG4,"S",C11:AG12) -> 76.5 | AN11: =SUMIF(C4:AG4,"G",C11:AG12) -> 0 | AO11: =AH11+'2026-04'!AO11 -> 0
AL12: =IF(SUM(C11:AG11)-AI11=0,"√",SUM(C11:AG11)-AI11) -> 97.5
A13: 5 | B13: 夏莉萍 | F13: 8.5 | G13: 8.5 | L13: 8.5 | M13: 3 | N13: 3 | O13: 调 | Q13: 3 | R13: 8.5 | S13: 8.5 | W13: 3 | Y13: 8.5 | Z13: 8.5 | AA13: 调 | AD13: 3 | AF13: 8.5 | AG13: 8.5 | AH13: =-(SUMIF(C13:AG13,"=年",C14:AG14)) -> 0 | AI13: =-(SUMIF(C13:AG13,"=调",C14:AG14)) -> 11 | AJ13: =-(SUMIF(C13:AG13,"=病",C14:AG14)) -> 0 | AK13: =-(SUMIF(C13:AG13,"=事",C14:AG14)) -> 0 | AL13: =SUMIF(C4:AG4,"P",C13:AG14) -> 15 | AM13: =SUMIF(C4:AG4,"S",C13:AG14) -> 76.5 | AN13: =SUMIF(C4:AG4,"G",C13:AG14) -> 0 | AO13: =AH13+'2026-04'!AO13 -> 18
O14: -8 | AA14: -3 | AL14: =IF(SUM(C13:AG13)-AI13=0,"√",SUM(C13:AG13)-AI13) -> 80.5
A15: 6 | B15: 徐启双 | D15: 6 | F15: 8.5 | G15: 8.5 | L15: 8.5 | M15: 3 | N15: 3 | R15: 8.5 | S15: 8.5 | T15: 3 | V15: 3 | W15: 3 | Y15: 8.5 | Z15: 8.5 | AD15: 3 | AF15: 8.5 | AG15: 8.5 | AH15: =-(SUMIF(C15:AG15,"=年",C16:AG16)) -> 0 | AI15: =-(SUMIF(C15:AG15,"=调",C16:AG16)) -> 0 | AJ15: =-(SUMIF(C15:AG15,"=病",C16:AG16)) -> 0 | AK15: =-(SUMIF(C15:AG15,"=事",C16:AG16)) -> 0 | AL15: =SUMIF(C4:AG4,"P",C15:AG16) -> 18 | AM15: =SUMIF(C4:AG4,"S",C15:AG16) -> 76.5 | AN15: =SUMIF(C4:AG4,"G",C15:AG16) -> 6 | AO15: =AH15+'2026-04'!AO15 -> 8
AL16: =IF(SUM(C15:AG15)-AI15=0,"√",SUM(C15:AG15)-AI15) -> 100.5
A17: 7 | B17: 张静 | AH17: =-(SUMIF(C17:AG17,"=年",C18:AG18)) -> 0 | AI17: =-(SUMIF(C17:AG17,"=调",C18:AG18)) -> 0 | AJ17: =-(SUMIF(C17:AG17,"=病",C18:AG18)) -> 0 | AK17: =-(SUMIF(C17:AG17,"=事",C18:AG18)) -> 0 | AL17: =SUMIF(C4:AG4,"P",C17:AG18) -> 0 | AM17: =SUMIF(C4:AG4,"S",C17:AG18) -> 0 | AN17: =SUMIF(C4:AG4,"G",C17:AG18) -> 0 | AO17: =AH17+'2026-04'!AO17 -> 13
AL18: =IF(SUM(C17:AG17)-AI17=0,"√",SUM(C17:AG17)-AI17) -> √
A19: 8 | B19: 尤文娟 | F19: 8.5 | G19: 8.5 | L19: 8.5 | M19: 3 | N19: 3 | Q19: 3 | R19: 8.5 | S19: 8.5 | T19: 年 | U19: 3 | V19: 3 | W19: 3 | Y19: 8.5 | Z19: 8.5 | AD19: 3 | AF19: 8.5 | AG19: 8.5 | AH19: =-(SUMIF(C19:AG19,"=年",C20:AG20)) -> 6.5 | AI19: =-(SUMIF(C19:AG19,"=调",C20:AG20)) -> 0 | AJ19: =-(SUMIF(C19:AG19,"=病",C20:AG20)) -> 0 | AK19: =-(SUMIF(C19:AG19,"=事",C20:AG20)) -> 0 | AL19: =SUMIF(C4:AG4,"P",C19:AG20) -> 21 | AM19: =SUMIF(C4:AG4,"S",C19:AG20) -> 76.5 | AN19: =SUMIF(C4:AG4,"G",C19:AG20) -> 0 | AO19: =AH19+'2026-04'!AO19 -> 6.5 | AP19: 为记载方便，19日年假合并记录进18日
T20: -6.5 | AL20: =IF(SUM(C19:AG19)-AI19=0,"√",SUM(C19:AG19)-AI19) -> 97.5
A21: 9 | B21: 夏卉 | E21: 5 | F21: 8.5 | G21: 8.5 | K21: 年 | L21: 8.5 | M21: 3 | N21: 3 | O21: 3 | R21: 8.5 | S21: 8.5 | U21: 3 | V21: 3 | W21: 3 | X21: 3 | Y21: 8.5 | Z21: 8.5 | AD21: 3 | AF21: 8.5 | AG21: 8.5 | AH21: =-(SUMIF(C21:AG21,"=年",C22:AG22)) -> 2 | AI21: =-(SUMIF(C21:AG21,"=调",C22:AG22)) -> 0 | AJ21: =-(SUMIF(C21:AG21,"=病",C22:AG22)) -> 0 | AK21: =-(SUMIF(C21:AG21,"=事",C22:AG22)) -> 0 | AL21: =SUMIF(C4:AG4,"P",C21:AG22) -> 24 | AM21: =SUMIF(C4:AG4,"S",C21:AG22) -> 76.5 | AN21: =SUMIF(C4:AG4,"G",C21:AG22) -> 5 | AO21: =AH21+'2026-04'!AO21 -> 4
K22: -2 | AL22: =IF(SUM(C21:AG21)-AI21=0,"√",SUM(C21:AG21)-AI21) -> 105.5
A23: 10 | B23: 惠雅 | C23: 3 | F23: 8.5 | G23: 8.5 | J23: 年 | L23: 8.5 | M23: 3 | N23: 3 | Q23: 3 | R23: 8.5 | S23: 8.5 | U23: 3 | V23: 3 | W23: 3 | Y23: 8.5 | Z23: 8.5 | AD23: 3 | AF23: 8.5 | AG23: 8.5 | AH23: =-(SUMIF(C23:AG23,"=年",C24:AG24)) -> 8 | AI23: =-(SUMIF(C23:AG23,"=调",C24:AG24)) -> 0 | AJ23: =-(SUMIF(C23:AG23,"=病",C24:AG24)) -> 0 | AK23: =-(SUMIF(C23:AG23,"=事",C24:AG24)) -> 0 | AL23: =SUMIF(C4:AG4,"P",C23:AG24) -> 21 | AM23: =SUMIF(C4:AG4,"S",C23:AG24) -> 76.5 | AN23: =SUMIF(C4:AG4,"G",C23:AG24) -> 3 | AO23: =AH23+'2026-04'!AO23 -> 11
J24: -8 | AL24: =IF(SUM(C23:AG23)-AI23=0,"√",SUM(C23:AG23)-AI23) -> 100.5
A25: 11 | B25: 张永妹 | F25: 8.5 | G25: 8.5 | I25: 年 | L25: 8.5 | M25: 3 | N25: 3 | O25: 3 | R25: 8.5 | S25: 8.5 | U25: 3 | V25: 3 | W25: 3 | Y25: 8.5 | Z25: 8.5 | AD25: 3 | AF25: 8.5 | AG25: 8.5 | AH25: =-(SUMIF(C25:AG25,"=年",C26:AG26)) -> 1 | AI25: =-(SUMIF(C25:AG25,"=调",C26:AG26)) -> 0 | AJ25: =-(SUMIF(C25:AG25,"=病",C26:AG26)) -> 0 | AK25: =-(SUMIF(C25:AG25,"=事",C26:AG26)) -> 0 | AL25: =SUMIF(C4:AG4,"P",C25:AG26) -> 21 | AM25: =SUMIF(C4:AG4,"S",C25:AG26) -> 76.5 | AN25: =SUMIF(C4:AG4,"G",C25:AG26) -> 0 | AO25: =AH25+'2026-04'!AO25 -> 33
I26: -1 | AL26: =IF(SUM(C25:AG25)-AI25=0,"√",SUM(C25:AG25)-AI25) -> 97.5
A27: 12 | B27: 亢亦宁 | I27: 年 | O27: 年 | Z27: 5 | AA27: 4.5 | AB27: 0.5 | AH27: =-(SUMIF(C27:AG27,"=年",C28:AG28)) -> 6.5 | AI27: =-(SUMIF(C27:AG27,"=调",C28:AG28)) -> 0 | AJ27: =-(SUMIF(C27:AG27,"=病",C28:AG28)) -> 0 | AK27: =-(SUMIF(C27:AG27,"=事",C28:AG28)) -> 0 | AL27: =SUMIF(C4:AG4,"P",C27:AG28) -> 5 | AM27: =SUMIF(C4:AG4,"S",C27:AG28)-AI27 -> 5 | AN27: =SUMIF(C4:AG4,"G",C27:AG28) -> 0 | AO27: =AH27+'2026-04'!AO27 -> 49.5
I28: -2.5 | O28: -4 | AL28: =IF(SUM(C27:AG27)-AI27=0,"√",SUM(C27:AG27)-AI27) -> 10
A29: 注：①“年”指年假； ②“病”指有薪病假； ③“事”指事假； ④单位：小时； ⑤“居”指居家办公；⑥调休优先抵扣优先级：双休日>国假>平时加班，调休后统计加班累计；
A30: 制表：（顾桢鸿） | S30: 审核：（马道旭） | AJ30: 核准：

Sheet 2026-06
A1: 苏州晶讯科技股份有限公司 品管部
A2: 序号 | B2: 姓名 | C2: 2026年6月出勤状况(工作日:22天) | AH2: 本月累计 | AO2: 年度 总计 年假 | AP2: 备注
C3: 1 | D3: 2 | E3: 3 | F3: 4 | G3: 5 | H3: 6 | I3: 7 | J3: 8 | K3: 9 | L3: 10 | M3: 11 | N3: 12 | O3: 13 | P3: 14 | Q3: 15 | R3: 16 | S3: 17 | T3: 18 | U3: 19 | V3: 20 | W3: 21 | X3: 22 | Y3: 23 | Z3: 24 | AA3: 25 | AB3: 26 | AC3: 27 | AD3: 28 | AE3: 29 | AF3: 30 | AG3: 5月 | AH3: 请假 | AL3: 加班
C4: P | D4: P | E4: P | F4: P | G4: P | H4: S | I4: S | J4: P | K4: P | L4: P | M4: P | N4: P | O4: S | P4: S | Q4: P | R4: P | S4: P | T4: P | U4: G | V4: S | W4: S | X4: P | Y4: P | Z4: P | AA4: P | AB4: P | AC4: S | AD4: S | AE4: P | AF4: P | AG4: P | AH4: 年假 | AI4: 调休 | AJ4: 病假 | AK4: 事假 | AL4: 平时 | AM4: 休息日 | AN4: 国假
A5: 1 | B5: 马道旭 | AH5: =-(SUMIF(C5:AG5,"=年",C6:AG6)) -> 0 | AI5: =-(SUMIF(C5:AG5,"=调",C6:AG6)) -> 0 | AJ5: =-(SUMIF(C5:AG5,"=病",C6:AG6)) -> 0 | AK5: =-(SUMIF(C5:AG5,"=事",C6:AG6)) -> 0 | AL5: =SUMIF(C4:AG4,"P",C5:AG6) -> 0 | AM5: =SUMIF(C4:AG4,"S",C5:AG6) -> 0 | AN5: =SUMIF(C4:AG4,"G",C5:AG6) -> 0 | AO5: =AH5+'2026-05'!AO5 -> 28
AL6: =IF(SUM(C5:AG5)-AI5=0,"√",SUM(C5:AG5)-AI5) -> √
A7: 2 | B7: 顾桢鸿 | J7: 年 | K7: 年 | AE7: 年 | AG7: 2.5 | AH7: =-(SUMIF(C7:AG7,"=年",C8:AG8)) -> 24 | AI7: =-(SUMIF(C7:AG7,"=调",C8:AG8)) -> 0 | AJ7: =-(SUMIF(C7:AG7,"=病",C8:AG8)) -> 0 | AK7: =-(SUMIF(C7:AG7,"=事",C8:AG8)) -> 0 | AL7: =SUMIF(C4:AG4,"P",C7:AG8) -> 2.5 | AM7: =SUMIF(C4:AG4,"S",C7:AG8) -> 0 | AN7: =SUMIF(C4:AG4,"G",C7:AG8) -> 0 | AO7: =AH7+'2026-05'!AO7 -> 60 | AP7: 5.29记入5月
J8: -8 | K8: -8 | AE8: -8 | AL8: =IF(SUM(C7:AG7)-AI7=0,"√",SUM(C7:AG7)-AI7) -> 2.5
A9: 3 | B9: 顾晓维 | G9: 3 | AH9: =-(SUMIF(C9:AG9,"=年",C10:AG10)) -> 0 | AI9: =-(SUMIF(C9:AG9,"=调",C10:AG10)) -> 0 | AJ9: =-(SUMIF(C9:AG9,"=病",C10:AG10)) -> 0 | AK9: =-(SUMIF(C9:AG9,"=事",C10:AG10)) -> 0 | AL9: =SUMIF(C4:AG4,"P",C9:AG10) -> 3 | AM9: =SUMIF(C4:AG4,"S",C9:AG10) -> 0 | AN9: =SUMIF(C4:AG4,"G",C9:AG10) -> 0 | AO9: =AH9+'2026-05'!AO9 -> 34
AL10: =IF(SUM(C9:AG9)-AI9=0,"√",SUM(C9:AG9)-AI9) -> 3
A11: 4 | B11: 吴丽娟 | C11: 年 | E11: 3 | H11: 8.5 | I11: 8.5 | O11: 8.5 | P11: 8.5 | U11: 8.5 | W11: 8.5 | AC11: 8.5 | AD11: 8.5 | AG11: 3 | AH11: =-(SUMIF(C11:AG11,"=年",C12:AG12)) -> 4 | AI11: =-(SUMIF(C11:AG11,"=调",C12:AG12)) -> 0 | AJ11: =-(SUMIF(C11:AG11,"=病",C12:AG12)) -> 0 | AK11: =-(SUMIF(C11:AG11,"=事",C12:AG12)) -> 0 | AL11: =SUMIF(C4:AG4,"P",C11:AG12) -> 6 | AM11: =SUMIF(C4:AG4,"S",C11:AG12) -> 59.5 | AN11: =SUMIF(C4:AG4,"G",C11:AG12) -> 8.5 | AO11: =AH11+'2026-05'!AO11 -> 4 | AP11: 5.29记入5月
C12: -4 | AL12: =IF(SUM(C11:AG11)-AI11=0,"√",SUM(C11:AG11)-AI11) -> 74
A13: 5 | B13: 夏莉萍 | E13: 3 | F13: 年 | H13: 8.5 | I13: 8.5 | O13: 8.5 | P13: 8.5 | U13: 8.5 | V13: 8.5 | W13: 8.5 | AC13: 8.5 | AD13: 8.5 | AG13: 3 | AH13: =-(SUMIF(C13:AG13,"=年",C14:AG14)) -> 3.5 | AI13: =-(SUMIF(C13:AG13,"=调",C14:AG14)) -> 0 | AJ13: =-(SUMIF(C13:AG13,"=病",C14:AG14)) -> 0 | AK13: =-(SUMIF(C13:AG13,"=事",C14:AG14)) -> 0 | AL13: =SUMIF(C4:AG4,"P",C13:AG14) -> 6 | AM13: =SUMIF(C4:AG4,"S",C13:AG14) -> 68 | AN13: =SUMIF(C4:AG4,"G",C13:AG14) -> 8.5 | AO13: =AH13+'2026-05'!AO13 -> 21.5 | AP13: 6.3年假记入6.4 5.29记入5月
F14: -3.5 | AL14: =IF(SUM(C13:AG13)-AI13=0,"√",SUM(C13:AG13)-AI13) -> 82.5
A15: 6 | B15: 徐启双 | D15: 3 | H15: 8.5 | I15: 8.5 | O15: 8.5 | P15: 8.5 | Q15: 年 | R15: 年 | U15: 8.5 | V15: 8.5 | W15: 8.5 | AC15: 8.5 | AG15: 6 | AH15: =-(SUMIF(C15:AG15,"=年",C16:AG16)) -> 7 | AI15: =-(SUMIF(C15:AG15,"=调",C16:AG16)) -> 0 | AJ15: =-(SUMIF(C15:AG15,"=病",C16:AG16)) -> 0 | AK15: =-(SUMIF(C15:AG15,"=事",C16:AG16)) -> 0 | AL15: =SUMIF(C4:AG4,"P",C15:AG16) -> 9 | AM15: =SUMIF(C4:AG4,"S",C15:AG16) -> 59.5 | AN15: =SUMIF(C4:AG4,"G",C15:AG16) -> 8.5 | AO15: =AH15+'2026-05'!AO15 -> 15 | AP15: 5.25、5.29记入5月
Q16: -4 | R16: -3 | AL16: =IF(SUM(C15:AG15)-AI15=0,"√",SUM(C15:AG15)-AI15) -> 77
A17: 7 | B17: 张静 | G17: 年 | AH17: =-(SUMIF(C17:AG17,"=年",C18:AG18)) -> 8 | AI17: =-(SUMIF(C17:AG17,"=调",C18:AG18)) -> 0 | AJ17: =-(SUMIF(C17:AG17,"=病",C18:AG18)) -> 0 | AK17: =-(SUMIF(C17:AG17,"=事",C18:AG18)) -> 0 | AL17: =SUMIF(C4:AG4,"P",C17:AG18) -> 0 | AM17: =SUMIF(C4:AG4,"S",C17:AG18) -> 0 | AN17: =SUMIF(C4:AG4,"G",C17:AG18) -> 0 | AO17: =AH17+'2026-05'!AO17 -> 21
G18: -8 | AL18: =IF(SUM(C17:AG17)-AI17=0,"√",SUM(C17:AG17)-AI17) -> √
A19: 8 | B19: 尤文娟 | G19: 3 | H19: 8.5 | I19: 8.5 | L19: 年 | O19: 8.5 | P19: 8.5 | V19: 8.5 | W19: 8.5 | AC19: 8.5 | AD19: 8.5 | AH19: =-(SUMIF(C19:AG19,"=年",C20:AG20)) -> 4 | AI19: =-(SUMIF(C19:AG19,"=调",C20:AG20)) -> 0 | AJ19: =-(SUMIF(C19:AG19,"=病",C20:AG20)) -> 0 | AK19: =-(SUMIF(C19:AG19,"=事",C20:AG20)) -> 0 | AL19: =SUMIF(C4:AG4,"P",C19:AG20) -> 3 | AM19: =SUMIF(C4:AG4,"S",C19:AG20) -> 68 | AN19: =SUMIF(C4:AG4,"G",C19:AG20) -> 0 | AO19: =AH19+'2026-05'!AO19 -> 10.5
L20: -4 | AL20: =IF(SUM(C19:AG19)-AI19=0,"√",SUM(C19:AG19)-AI19) -> 71
A21: 9 | B21: 夏卉 | E21: 年 | F21: 3 | H21: 8.5 | I21: 8.5 | M21: 年 | O21: 8.5 | P21: 8.5 | U21: 8.5 | V21: 8.5 | AC21: 8.5 | AD21: 8.5 | AH21: =-(SUMIF(C21:AG21,"=年",C22:AG22)) -> 2 | AI21: =-(SUMIF(C21:AG21,"=调",C22:AG22)) -> 0 | AJ21: =-(SUMIF(C21:AG21,"=病",C22:AG22)) -> 0 | AK21: =-(SUMIF(C21:AG21,"=事",C22:AG22)) -> 0 | AL21: =SUMIF(C4:AG4,"P",C21:AG22) -> 3 | AM21: =SUMIF(C4:AG4,"S",C21:AG22) -> 59.5 | AN21: =SUMIF(C4:AG4,"G",C21:AG22) -> 8.5 | AO21: =AH21+'2026-05'!AO21 -> 6 | AP21: 6.4年假记入6.3
E22: -1 | M22: -1 | AL22: =IF(SUM(C21:AG21)-AI21=0,"√",SUM(C21:AG21)-AI21) -> 71
A23: 10 | B23: 惠雅 | G23: 3 | H23: 8.5 | I23: 8.5 | O23: 8.5 | P23: 8.5 | U23: 8.5 | V23: 8.5 | W23: 8.5 | Y23: 年 | AC23: 8.5 | AD23: 8.5 | AG23: 3 | AH23: =-(SUMIF(C23:AG23,"=年",C24:AG24)) -> 2 | AI23: =-(SUMIF(C23:AG23,"=调",C24:AG24)) -> 0 | AJ23: =-(SUMIF(C23:AG23,"=病",C24:AG24)) -> 0 | AK23: =-(SUMIF(C23:AG23,"=事",C24:AG24)) -> 0 | AL23: =SUMIF(C4:AG4,"P",C23:AG24) -> 6 | AM23: =SUMIF(C4:AG4,"S",C23:AG24) -> 68 | AN23: =SUMIF(C4:AG4,"G",C23:AG24) -> 8.5 | AO23: =AH23+'2026-05'!AO23 -> 13 | AP23: 5.29记入5月
Y24: -2 | AL24: =IF(SUM(C23:AG23)-AI23=0,"√",SUM(C23:AG23)-AI23) -> 82.5
A25: 11 | B25: 张永妹 | F25: 3 | H25: 8.5 | I25: 8.5 | O25: 8.5 | P25: 8.5 | U25: 8.5 | V25: 8.5 | W25: 8.5 | AC25: 8.5 | AD25: 8.5 | AG25: 3 | AH25: =-(SUMIF(C25:AG25,"=年",C26:AG26)) -> 0 | AI25: =-(SUMIF(C25:AG25,"=调",C26:AG26)) -> 0 | AJ25: =-(SUMIF(C25:AG25,"=病",C26:AG26)) -> 0 | AK25: =-(SUMIF(C25:AG25,"=事",C26:AG26)) -> 0 | AL25: =SUMIF(C4:AG4,"P",C25:AG26) -> 6 | AM25: =SUMIF(C4:AG4,"S",C25:AG26) -> 68 | AN25: =SUMIF(C4:AG4,"G",C25:AG26) -> 8.5 | AO25: =AH25+'2026-05'!AO25 -> 33 | AP25: 5.29记入5月
AL26: =IF(SUM(C25:AG25)-AI25=0,"√",SUM(C25:AG25)-AI25) -> 82.5
A27: 12 | B27: 亢亦宁 | AH27: =-(SUMIF(C27:AG27,"=年",C28:AG28)) -> 0 | AI27: =-(SUMIF(C27:AG27,"=调",C28:AG28)) -> 0 | AJ27: =-(SUMIF(C27:AG27,"=病",C28:AG28)) -> 0 | AK27: =-(SUMIF(C27:AG27,"=事",C28:AG28)) -> 0 | AL27: =SUMIF(C4:AG4,"P",C27:AG28) -> 0 | AM27: =SUMIF(C4:AG4,"S",C27:AG28)-AI27 -> 0 | AN27: =SUMIF(C4:AG4,"G",C27:AG28) -> 0 | AO27: =AH27+'2026-05'!AO27 -> 49.5
AL28: =IF(SUM(C27:AG27)-AI27=0,"√",SUM(C27:AG27)-AI27) -> √
A29: 注：①“年”指年假； ②“病”指有薪病假； ③“事”指事假； ④单位：小时； ⑤“居”指居家办公；⑥调休优先抵扣优先级：双休日>国假>平时加班，调休后统计加班累计；
A30: 制表：（顾桢鸿） | S30: 审核：（马道旭） | AJ30: 核准：

Sheet 2026-07
A1: 苏州晶讯科技股份有限公司 品管部
A2: 序号 | B2: 姓名 | C2: 2026年7月出勤状况(工作日:23天) | AH2: 本月累计 | AP2: 年度 总计 年假 | AQ2: 备注
C3: 1 | D3: 2 | E3: 3 | F3: 4 | G3: 5 | H3: 6 | I3: 7 | J3: 8 | K3: 9 | L3: 10 | M3: 11 | N3: 12 | O3: 13 | P3: 14 | Q3: 15 | R3: 16 | S3: 17 | T3: 18 | U3: 19 | V3: 20 | W3: 21 | X3: 22 | Y3: 23 | Z3: 24 | AA3: 25 | AB3: 26 | AC3: 27 | AD3: 28 | AE3: 29 | AF3: 30 | AG3: 31 | AH3: 请假 | AM3: 加班
C4: P | D4: P | E4: P | F4: S | G4: S | H4: P | I4: P | J4: P | K4: P | L4: P | M4: S | N4: S | O4: P | P4: P | Q4: P | R4: P | S4: P | T4: S | U4: S | V4: P | W4: P | X4: P | Y4: P | Z4: P | AA4: S | AB4: S | AC4: P | AD4: P | AE4: P | AF4: P | AG4: P | AH4: 其它 | AI4: 年假 | AJ4: 调休 | AK4: 病假 | AL4: 事假 | AM4: 平时 | AN4: 休息日 | AO4: 国假
A5: 1 | B5: 马道旭 | I5: 年 | AH5: {=-SUMPRODUCT((C5:AG5<>"年") * (C5:AG5<>"调") * (C5:AG5<>"病") * (C5:AG5<>"事") * C6:AG6)} -> 0 | AI5: =-(SUMIF(C5:AG5,"=年",C6:AG6)) -> 3.5 | AJ5: =-(SUMIF(C5:AG5,"=调",C6:AG6)) -> 0 | AK5: =-(SUMIF(C5:AG5,"=病",C6:AG6)) -> 0 | AL5: =-(SUMIF(C5:AG5,"=事",C6:AG6)) -> 0 | AM5: =SUMIF(C4:AG4,"P",C5:AG6) -> 0 | AN5: =SUMIF(C4:AG4,"S",C5:AG6) -> 0 | AO5: =SUMIF(C4:AG4,"G",C5:AG6) -> 0 | AP5: =AI5+'2026-06'!AO5 -> 31.5
I6: -3.5 | AM6: =IF(SUM(C5:AG5)-AJ5=0,"√",SUM(C5:AG5)-AJ5) -> √
A7: 2 | B7: 顾桢鸿 | AH7: {=-SUMPRODUCT((C7:AG7<>"年") * (C7:AG7<>"调") * (C7:AG7<>"病") * (C7:AG7<>"事") * C8:AG8)} -> 0 | AI7: =-(SUMIF(C7:AG7,"=年",C8:AG8)) -> 0 | AJ7: =-(SUMIF(C7:AG7,"=调",C8:AG8)) -> 0 | AK7: =-(SUMIF(C7:AG7,"=病",C8:AG8)) -> 0 | AL7: =-(SUMIF(C7:AG7,"=事",C8:AG8)) -> 0 | AM7: =SUMIF(C4:AG4,"P",C7:AG8) -> 0 | AN7: =SUMIF(C4:AG4,"S",C7:AG8) -> 0 | AO7: =SUMIF(C4:AG4,"G",C7:AG8) -> 0 | AP7: =AI7+'2026-06'!AO7 -> 60
AM8: =IF(SUM(C7:AG7)-AJ7=0,"√",SUM(C7:AG7)-AJ7) -> √
A9: 3 | B9: 顾晓维 | AE9: 独 | AF9: 独 | AH9: {=-SUMPRODUCT((C9:AG9<>"年") * (C9:AG9<>"调") * (C9:AG9<>"病") * (C9:AG9<>"事") * C10:AG10)} -> 5.5 | AI9: =-(SUMIF(C9:AG9,"=年",C10:AG10)) -> 0 | AJ9: =-(SUMIF(C9:AG9,"=调",C10:AG10)) -> 0 | AK9: =-(SUMIF(C9:AG9,"=病",C10:AG10)) -> 0 | AL9: =-(SUMIF(C9:AG9,"=事",C10:AG10)) -> 0 | AM9: =SUMIF(C4:AG4,"P",C9:AG10) -> 0 | AN9: =SUMIF(C4:AG4,"S",C9:AG10) -> 0 | AO9: =SUMIF(C4:AG4,"G",C9:AG10) -> 0 | AP9: =AI9+'2026-06'!AO9 -> 34
AE10: -4 | AF10: -1.5 | AM10: =IF(SUM(C9:AG9)-AJ9=0,"√",SUM(C9:AG9)-AJ9) -> √
A11: 4 | B11: 吴丽娟 | F11: 8.5 | G11: 8.5 | N11: 8.5 | T11: 8.5 | U11: 8.5 | X11: 3 | Y11: 3 | Z11: 3 | AA11: 11.5 | AB11: 8.5 | AH11: {=-SUMPRODUCT((C11:AG11<>"年") * (C11:AG11<>"调") * (C11:AG11<>"病") * (C11:AG11<>"事") * C12:AG12)} -> 0 | AI11: =-(SUMIF(C11:AG11,"=年",C12:AG12)) -> 0 | AJ11: =-(SUMIF(C11:AG11,"=调",C12:AG12)) -> 0 | AK11: =-(SUMIF(C11:AG11,"=病",C12:AG12)) -> 0 | AL11: =-(SUMIF(C11:AG11,"=事",C12:AG12)) -> 0 | AM11: =SUMIF(C4:AG4,"P",C11:AG12) -> 9 | AN11: =SUMIF(C4:AG4,"S",C11:AG12) -> 62.5 | AO11: =SUMIF(C4:AG4,"G",C11:AG12) -> 0 | AP11: =AI11+'2026-06'!AO11 -> 4
AM12: =IF(SUM(C11:AG11)-AJ11=0,"√",SUM(C11:AG11)-AJ11) -> 71.5
A13: 5 | B13: 夏莉萍 | F13: 8.5 | G13: 8.5 | M13: 8.5 | N13: 8.5 | Q13: 调 | R13: 调 | S13: 调 | X13: 调 | AA13: 8.5 | AB13: 11.5 | AC13: 调 | AH13: {=-SUMPRODUCT((C13:AG13<>"年") * (C13:AG13<>"调") * (C13:AG13<>"病") * (C13:AG13<>"事") * C14:AG14)} -> 0 | AI13: =-(SUMIF(C13:AG13,"=年",C14:AG14)) -> 0 | AJ13: =-(SUMIF(C13:AG13,"=调",C14:AG14)) -> 31 | AK13: =-(SUMIF(C13:AG13,"=病",C14:AG14)) -> 0 | AL13: =-(SUMIF(C13:AG13,"=事",C14:AG14)) -> 0 | AM13: =SUMIF(C4:AG4,"P",C13:AG14) -> 0 | AN13: =SUMIF(C4:AG4,"S",C13:AG14) -> 54 | AO13: =SUMIF(C4:AG4,"G",C13:AG14) -> 0 | AP13: =AI13+'2026-06'!AO13 -> 21.5
Q14: -8 | R14: -8 | S14: -8 | X14: -4 | AC14: -3 | AM14: =IF(SUM(C13:AG13)-AJ13=0,"√",SUM(C13:AG13)-AJ13) -> 23
A15: 6 | B15: 徐启双 | C15: 3 | F15: 8.5 | G15: 8.5 | H15: 3 | M15: 8.5 | N15: 8.5 | Q15: 3 | R15: 3 | T15: 8.5 | U15: 8.5 | W15: 3 | X15: 3 | Y15: 3 | Z15: 3 | AA15: 11.5 | AB15: 8.5 | AH15: {=-SUMPRODUCT((C15:AG15<>"年") * (C15:AG15<>"调") * (C15:AG15<>"病") * (C15:AG15<>"事") * C16:AG16)} -> 0 | AI15: =-(SUMIF(C15:AG15,"=年",C16:AG16)) -> 0 | AJ15: =-(SUMIF(C15:AG15,"=调",C16:AG16)) -> 0 | AK15: =-(SUMIF(C15:AG15,"=病",C16:AG16)) -> 0 | AL15: =-(SUMIF(C15:AG15,"=事",C16:AG16)) -> 0 | AM15: =SUMIF(C4:AG4,"P",C15:AG16) -> 24 | AN15: =SUMIF(C4:AG4,"S",C15:AG16) -> 71 | AO15: =SUMIF(C4:AG4,"G",C15:AG16) -> 0 | AP15: =AI15+'2026-06'!AO15 -> 15 | AQ15: 6.30加班记入7.1
AM16: =IF(SUM(C15:AG15)-AJ15=0,"√",SUM(C15:AG15)-AJ15) -> 95
A17: 7 | B17: 张静 | R17: 年 | AH17: {=-SUMPRODUCT((C17:AG17<>"年") * (C17:AG17<>"调") * (C17:AG17<>"病") * (C17:AG17<>"事") * C18:AG18)} -> 0 | AI17: =-(SUMIF(C17:AG17,"=年",C18:AG18)) -> 4 | AJ17: =-(SUMIF(C17:AG17,"=调",C18:AG18)) -> 0 | AK17: =-(SUMIF(C17:AG17,"=病",C18:AG18)) -> 0 | AL17: =-(SUMIF(C17:AG17,"=事",C18:AG18)) -> 0 | AM17: =SUMIF(C4:AG4,"P",C17:AG18) -> 0 | AN17: =SUMIF(C4:AG4,"S",C17:AG18) -> 0 | AO17: =SUMIF(C4:AG4,"G",C17:AG18) -> 0 | AP17: =AI17+'2026-06'!AO17 -> 25
R18: -4 | AM18: =IF(SUM(C17:AG17)-AJ17=0,"√",SUM(C17:AG17)-AJ17) -> √
A19: 8 | B19: 尤文娟 | F19: 8.5 | H19: 3 | I19: 年 | M19: 8.5 | N19: 8.5 | T19: 8.5 | U19: 8.5 | V19: 年 | X19: 3 | Z19: 3 | AA19: 8.5 | AB19: 11.5 | AH19: {=-SUMPRODUCT((C19:AG19<>"年") * (C19:AG19<>"调") * (C19:AG19<>"病") * (C19:AG19<>"事") * C20:AG20)} -> 0 | AI19: =-(SUMIF(C19:AG19,"=年",C20:AG20)) -> 16 | AJ19: =-(SUMIF(C19:AG19,"=调",C20:AG20)) -> 0 | AK19: =-(SUMIF(C19:AG19,"=病",C20:AG20)) -> 0 | AL19: =-(SUMIF(C19:AG19,"=事",C20:AG20)) -> 0 | AM19: =SUMIF(C4:AG4,"P",C19:AG20) -> 9 | AN19: =SUMIF(C4:AG4,"S",C19:AG20) -> 62.5 | AO19: =SUMIF(C4:AG4,"G",C19:AG20) -> 0 | AP19: =AI19+'2026-06'!AO19 -> 26.5
I20: -8 | V20: -8 | AM20: =IF(SUM(C19:AG19)-AJ19=0,"√",SUM(C19:AG19)-AJ19) -> 71.5
A21: 9 | B21: 夏卉 | C21: 年 | F21: 8.5 | G21: 8.5 | M21: 8.5 | O21: 年 | P21: 年 | Q21: 年 | T21: 8.5 | U21: 8.5 | X21: 3 | Y21: 3 | AA21: 11.5 | AB21: 11.5 | AD21: 年 | AH21: {=-SUMPRODUCT((C21:AG21<>"年") * (C21:AG21<>"调") * (C21:AG21<>"病") * (C21:AG21<>"事") * C22:AG22)} -> 0 | AI21: =-(SUMIF(C21:AG21,"=年",C22:AG22)) -> 31 | AJ21: =-(SUMIF(C21:AG21,"=调",C22:AG22)) -> 0 | AK21: =-(SUMIF(C21:AG21,"=病",C22:AG22)) -> 0 | AL21: =-(SUMIF(C21:AG21,"=事",C22:AG22)) -> 0 | AM21: =SUMIF(C4:AG4,"P",C21:AG22) -> 6 | AN21: =SUMIF(C4:AG4,"S",C21:AG22) -> 65.5 | AO21: =SUMIF(C4:AG4,"G",C21:AG22) -> 0 | AP21: =AI21+'2026-06'!AO21 -> 37
C22: -4 | O22: -8 | P22: -8 | Q22: -8 | AD22: -3 | AM22: =IF(SUM(C21:AG21)-AJ21=0,"√",SUM(C21:AG21)-AJ21) -> 71.5
A23: 10 | B23: 惠雅 | G23: 8.5 | M23: 8.5 | N23: 8.5 | T23: 8.5 | U23: 8.5 | X23: 3 | Y23: 3 | Z23: 3 | AA23: 8.5 | AB23: 11.5 | AH23: {=-SUMPRODUCT((C23:AG23<>"年") * (C23:AG23<>"调") * (C23:AG23<>"病") * (C23:AG23<>"事") * C24:AG24)} -> 0 | AI23: =-(SUMIF(C23:AG23,"=年",C24:AG24)) -> 0 | AJ23: =-(SUMIF(C23:AG23,"=调",C24:AG24)) -> 0 | AK23: =-(SUMIF(C23:AG23,"=病",C24:AG24)) -> 0 | AL23: =-(SUMIF(C23:AG23,"=事",C24:AG24)) -> 0 | AM23: =SUMIF(C4:AG4,"P",C23:AG24) -> 9 | AN23: =SUMIF(C4:AG4,"S",C23:AG24) -> 62.5 | AO23: =SUMIF(C4:AG4,"G",C23:AG24) -> 0 | AP23: =AI23+'2026-06'!AO23 -> 13
AM24: =IF(SUM(C23:AG23)-AJ23=0,"√",SUM(C23:AG23)-AJ23) -> 71.5
A25: 11 | B25: 张永妹 | F25: 8.5 | G25: 8.5 | M25: 8.5 | N25: 8.5 | T25: 8.5 | U25: 8.5 | W25: 年 | X25: 3 | AA25: 8.5 | AB25: 11.5 | AH25: {=-SUMPRODUCT((C25:AG25<>"年") * (C25:AG25<>"调") * (C25:AG25<>"病") * (C25:AG25<>"事") * C26:AG26)} -> 0 | AI25: =-(SUMIF(C25:AG25,"=年",C26:AG26)) -> 1 | AJ25: =-(SUMIF(C25:AG25,"=调",C26:AG26)) -> 0 | AK25: =-(SUMIF(C25:AG25,"=病",C26:AG26)) -> 0 | AL25: =-(SUMIF(C25:AG25,"=事",C26:AG26)) -> 0 | AM25: =SUMIF(C4:AG4,"P",C25:AG26) -> 3 | AN25: =SUMIF(C4:AG4,"S",C25:AG26) -> 71 | AO25: =SUMIF(C4:AG4,"G",C25:AG26) -> 0 | AP25: =AI25+'2026-06'!AO25 -> 34
W26: -1 | AM26: =IF(SUM(C25:AG25)-AJ25=0,"√",SUM(C25:AG25)-AJ25) -> 74
A27: 12 | B27: 亢亦宁 | V27: 年 | Z27: 年 | AH27: {=-SUMPRODUCT((C27:AG27<>"年") * (C27:AG27<>"调") * (C27:AG27<>"病") * (C27:AG27<>"事") * C28:AG28)} -> 0 | AI27: =-(SUMIF(C27:AG27,"=年",C28:AG28)) -> 7 | AJ27: =-(SUMIF(C27:AG27,"=调",C28:AG28)) -> 0 | AK27: =-(SUMIF(C27:AG27,"=病",C28:AG28)) -> 0 | AL27: =-(SUMIF(C27:AG27,"=事",C28:AG28)) -> 0 | AM27: =SUMIF(C4:AG4,"P",C27:AG28) -> 0 | AN27: =SUMIF(C4:AG4,"S",C27:AG28)-AJ27 -> 0 | AO27: =SUMIF(C4:AG4,"G",C27:AG28) -> 0 | AP27: =AI27+'2026-06'!AO27 -> 56.5
V28: -1.5 | Z28: -5.5 | AM28: =IF(SUM(C27:AG27)-AJ27=0,"√",SUM(C27:AG27)-AJ27) -> √
A29: 13 | B29: 赵婷 | AD29: 0.5 | AH29: {=-SUMPRODUCT((C29:AG29<>"年") * (C29:AG29<>"调") * (C29:AG29<>"病") * (C29:AG29<>"事") * C30:AG30)} -> 0 | AI29: =-(SUMIF(C29:AG29,"=年",C30:AG30)) -> 0 | AJ29: =-(SUMIF(C29:AG29,"=调",C30:AG30)) -> 0 | AK29: =-(SUMIF(C29:AG29,"=病",C30:AG30)) -> 0 | AL29: =-(SUMIF(C29:AG29,"=事",C30:AG30)) -> 0 | AM29: =SUMIF(C4:AG4,"P",C29:AG30) -> 0.5 | AN29: =SUMIF(C4:AG4,"S",C29:AG30)-AJ29 -> 0 | AO29: =SUMIF(C4:AG4,"G",C29:AG30) -> 0 | AP29: =AI29+'2026-06'!AO29 -> 0
AM30: =IF(SUM(C29:AG29)-AJ29=0,"√",SUM(C29:AG29)-AJ29) -> 0.5
A31: 注：①“年”-年假；“病”-有薪病假；“事”-事假；“独”-独生子女陪护假；“居”-居家办公 ②单位：小时；③调休优先抵扣优先级：双休日>国假>平时加班，调休后统计加班累计；
A32: 制表：（顾桢鸿） | S32: 审核：（马道旭） | AK32: 核准：

Sheet 2026-08
A1: 苏州晶讯科技股份有限公司 品管部
A2: 序号 | B2: 姓名 | C2: ="2026年8月出勤状况(工作日:"&COUNTIF(C4:AG4, "P")&"天)" -> 2026年8月出勤状况(工作日:21天) | AH2: 本月累计 | AP2: 年度 总计 年假 | AQ2: 备注
C3: 1 | D3: 2 | E3: 3 | F3: 4 | G3: 5 | H3: 6 | I3: 7 | J3: 8 | K3: 9 | L3: 10 | M3: 11 | N3: 12 | O3: 13 | P3: 14 | Q3: 15 | R3: 16 | S3: 17 | T3: 18 | U3: 19 | V3: 20 | W3: 21 | X3: 22 | Y3: 23 | Z3: 24 | AA3: 25 | AB3: 26 | AC3: 27 | AD3: 28 | AE3: 29 | AF3: 30 | AG3: 31 | AH3: 请假 | AM3: 加班
C4: S | D4: S | E4: P | F4: P | G4: P | H4: P | I4: P | J4: S | K4: S | L4: P | M4: P | N4: P | O4: P | P4: P | Q4: S | R4: S | S4: P | T4: P | U4: P | V4: P | W4: P | X4: S | Y4: S | Z4: P | AA4: P | AB4: P | AC4: P | AD4: P | AE4: S | AF4: S | AG4: P | AH4: 其 | AI4: 年 | AJ4: 调 | AK4: 病 | AL4: 事 | AM4: 平 | AN4: 休 | AO4: 国
A5: 1 | B5: 马道旭 | AG5: 年 | AH5: {=-SUMPRODUCT((C5:AG5<>"年") * (C5:AG5<>"调") * (C5:AG5<>"病") * (C5:AG5<>"事") * C6:AG6)} -> 0 | AI5: =-(SUMIF(C5:AG5,"=年",C6:AG6)) -> 2 | AJ5: =-(SUMIF(C5:AG5,"=调",C6:AG6)) -> 0 | AK5: =-(SUMIF(C5:AG5,"=病",C6:AG6)) -> 0 | AL5: =-(SUMIF(C5:AG5,"=事",C6:AG6)) -> 0 | AM5: =SUMIF(C4:AG4,"P",C5:AG6) -> 0 | AN5: =SUMIF(C4:AG4,"S",C5:AG6) -> 0 | AO5: =SUMIF(C4:AG4,"G",C5:AG6) -> 0 | AP5: =AI5+'2026-07'!AP5 -> 33.5 | AQ5: 7.31记入8.31
AG6: -2 | AM6: =IF(SUM(C5:AG5)-AJ5=0,"√",SUM(C5:AG5)-AJ5) -> √
A7: 2 | B7: 顾桢鸿 | N7: 年 | AH7: {=-SUMPRODUCT((C7:AG7<>"年") * (C7:AG7<>"调") * (C7:AG7<>"病") * (C7:AG7<>"事") * C8:AG8)} -> 0 | AI7: =-(SUMIF(C7:AG7,"=年",C8:AG8)) -> 8 | AJ7: =-(SUMIF(C7:AG7,"=调",C8:AG8)) -> 0 | AK7: =-(SUMIF(C7:AG7,"=病",C8:AG8)) -> 0 | AL7: =-(SUMIF(C7:AG7,"=事",C8:AG8)) -> 0 | AM7: =SUMIF(C4:AG4,"P",C7:AG8) -> 0 | AN7: =SUMIF(C4:AG4,"S",C7:AG8) -> 0 | AO7: =SUMIF(C4:AG4,"G",C7:AG8) -> 0 | AP7: =AI7+'2026-07'!AP7 -> 68
N8: -8 | AM8: =IF(SUM(C7:AG7)-AJ7=0,"√",SUM(C7:AG7)-AJ7) -> √
A9: 3 | B9: 顾晓维 | F9: 独 | Q9: 3 | AH9: {=-SUMPRODUCT((C9:AG9<>"年") * (C9:AG9<>"调") * (C9:AG9<>"病") * (C9:AG9<>"事") * C10:AG10)} -> 6 | AI9: =-(SUMIF(C9:AG9,"=年",C10:AG10)) -> 0 | AJ9: =-(SUMIF(C9:AG9,"=调",C10:AG10)) -> 0 | AK9: =-(SUMIF(C9:AG9,"=病",C10:AG10)) -> 0 | AL9: =-(SUMIF(C9:AG9,"=事",C10:AG10)) -> 0 | AM9: =SUMIF(C4:AG4,"P",C9:AG10) -> 0 | AN9: =SUMIF(C4:AG4,"S",C9:AG10) -> 3 | AO9: =SUMIF(C4:AG4,"G",C9:AG10) -> 0 | AP9: =AI9+'2026-07'!AP9 -> 34
F10: -6 | AM10: =IF(SUM(C9:AG9)-AJ9=0,"√",SUM(C9:AG9)-AJ9) -> 3
A11: 4 | B11: 吴丽娟 | C11: 8.5 | D11: 8.5 | J11: 8.5 | K11: 8.5 | Q11: 8.5 | U11: 3 | V11: 3 | X11: 8.5 | AE11: 8.5 | AF11: 8.5 | AH11: {=-SUMPRODUCT((C11:AG11<>"年") * (C11:AG11<>"调") * (C11:AG11<>"病") * (C11:AG11<>"事") * C12:AG12)} -> 0 | AI11: =-(SUMIF(C11:AG11,"=年",C12:AG12)) -> 0 | AJ11: =-(SUMIF(C11:AG11,"=调",C12:AG12)) -> 0 | AK11: =-(SUMIF(C11:AG11,"=病",C12:AG12)) -> 0 | AL11: =-(SUMIF(C11:AG11,"=事",C12:AG12)) -> 0 | AM11: =SUMIF(C4:AG4,"P",C11:AG12) -> 6 | AN11: =SUMIF(C4:AG4,"S",C11:AG12) -> 68 | AO11: =SUMIF(C4:AG4,"G",C11:AG12) -> 0 | AP11: =AI11+'2026-07'!AP11 -> 4
AM12: =IF(SUM(C11:AG11)-AJ11=0,"√",SUM(C11:AG11)-AJ11) -> 74
A13: 5 | B13: 夏莉萍 | D13: 8.5 | J13: 8.5 | K13: 8.5 | M13: 调 | Q13: 8.5 | S13: 调 | X13: 8.5 | AB13: 调 | AC13: 调 | AE13: 8.5 | AF13: 8.5 | AH13: {=-SUMPRODUCT((C13:AG13<>"年") * (C13:AG13<>"调") * (C13:AG13<>"病") * (C13:AG13<>"事") * C14:AG14)} -> 0 | AI13: =-(SUMIF(C13:AG13,"=年",C14:AG14)) -> 0 | AJ13: =-(SUMIF(C13:AG13,"=调",C14:AG14)) -> 15 | AK13: =-(SUMIF(C13:AG13,"=病",C14:AG14)) -> 0 | AL13: =-(SUMIF(C13:AG13,"=事",C14:AG14)) -> 0 | AM13: =SUMIF(C4:AG4,"P",C13:AG14) -> 0 | AN13: =SUMIF(C4:AG4,"S",C13:AG14) -> 59.5 | AO13: =SUMIF(C4:AG4,"G",C13:AG14) -> 0 | AP13: =AI13+'2026-07'!AP13 -> 21.5
M14: -3 | S14: -2 | AB14: -2 | AC14: -8 | AM14: =IF(SUM(C13:AG13)-AJ13=0,"√",SUM(C13:AG13)-AJ13) -> 44.5
A15: 6 | B15: 徐启双 | D15: 8.5 | J15: 8.5 | K15: 8.5 | Q15: 8.5 | R15: 8.5 | Y15: 8.5 | AA15: 3 | AB15: 3 | AC15: 3 | AD15: 3 | AE15: 11.5 | AF15: 11.5 | AH15: {=-SUMPRODUCT((C15:AG15<>"年") * (C15:AG15<>"调") * (C15:AG15<>"病") * (C15:AG15<>"事") * C16:AG16)} -> 0 | AI15: =-(SUMIF(C15:AG15,"=年",C16:AG16)) -> 0 | AJ15: =-(SUMIF(C15:AG15,"=调",C16:AG16)) -> 0 | AK15: =-(SUMIF(C15:AG15,"=病",C16:AG16)) -> 0 | AL15: =-(SUMIF(C15:AG15,"=事",C16:AG16)) -> 0 | AM15: =SUMIF(C4:AG4,"P",C15:AG16) -> 12 | AN15: =SUMIF(C4:AG4,"S",C15:AG16) -> 74 | AO15: =SUMIF(C4:AG4,"G",C15:AG16) -> 0 | AP15: =AI15+'2026-07'!AP15 -> 15
AM16: =IF(SUM(C15:AG15)-AJ15=0,"√",SUM(C15:AG15)-AJ15) -> 86
A17: 7 | B17: 张静 | G17: 年 | I17: 年 | AH17: {=-SUMPRODUCT((C17:AG17<>"年") * (C17:AG17<>"调") * (C17:AG17<>"病") * (C17:AG17<>"事") * C18:AG18)} -> 0 | AI17: =-(SUMIF(C17:AG17,"=年",C18:AG18)) -> 8 | AJ17: =-(SUMIF(C17:AG17,"=调",C18:AG18)) -> 0 | AK17: =-(SUMIF(C17:AG17,"=病",C18:AG18)) -> 0 | AL17: =-(SUMIF(C17:AG17,"=事",C18:AG18)) -> 0 | AM17: =SUMIF(C4:AG4,"P",C17:AG18) -> 0 | AN17: =SUMIF(C4:AG4,"S",C17:AG18) -> 0 | AO17: =SUMIF(C4:AG4,"G",C17:AG18) -> 0 | AP17: =AI17+'2026-07'!AP17 -> 33
G18: -4 | I18: -4 | AM18: =IF(SUM(C17:AG17)-AJ17=0,"√",SUM(C17:AG17)-AJ17) -> √
A19: 8 | B19: 尤文娟 | C19: 8.5 | D19: 8.5 | J19: 8.5 | K19: 8.5 | N19: 3.5 | O19: 年 | Q19: 8.5 | R19: 8.5 | X19: 8.5 | Y19: 8.5 | AE19: 8.5 | AF19: 8.5 | AH19: {=-SUMPRODUCT((C19:AG19<>"年") * (C19:AG19<>"调") * (C19:AG19<>"病") * (C19:AG19<>"事") * C20:AG20)} -> 0 | AI19: =-(SUMIF(C19:AG19,"=年",C20:AG20)) -> 8 | AJ19: =-(SUMIF(C19:AG19,"=调",C20:AG20)) -> 0 | AK19: =-(SUMIF(C19:AG19,"=病",C20:AG20)) -> 0 | AL19: =-(SUMIF(C19:AG19,"=事",C20:AG20)) -> 0 | AM19: =SUMIF(C4:AG4,"P",C19:AG20) -> 3.5 | AN19: =SUMIF(C4:AG4,"S",C19:AG20) -> 85 | AO19: =SUMIF(C4:AG4,"G",C19:AG20) -> 0 | AP19: =AI19+'2026-07'!AP19 -> 34.5
O20: -8 | AM20: =IF(SUM(C19:AG19)-AJ19=0,"√",SUM(C19:AG19)-AJ19) -> 88.5
A21: 9 | B21: 夏卉 | C21: 8.5 | D21: 8.5 | E21: 病 | Q21: 8.5 | R21: 8.5 | Y21: 8.5 | Z21: 年 | AF21: 8.5 | AH21: {=-SUMPRODUCT((C21:AG21<>"年") * (C21:AG21<>"调") * (C21:AG21<>"病") * (C21:AG21<>"事") * C22:AG22)} -> 0 | AI21: =-(SUMIF(C21:AG21,"=年",C22:AG22)) -> 8 | AJ21: =-(SUMIF(C21:AG21,"=调",C22:AG22)) -> 0 | AK21: =-(SUMIF(C21:AG21,"=病",C22:AG22)) -> 40 | AL21: =-(SUMIF(C21:AG21,"=事",C22:AG22)) -> 0 | AM21: =SUMIF(C4:AG4,"P",C21:AG22) -> 0 | AN21: =SUMIF(C4:AG4,"S",C21:AG22) -> 51 | AO21: =SUMIF(C4:AG4,"G",C21:AG22) -> 0 | AP21: =AI21+'2026-07'!AP21 -> 45
E22: -40 | Z22: -8 | AM22: =IF(SUM(C21:AG21)-AJ21=0,"√",SUM(C21:AG21)-AJ21) -> 51
A23: 10 | B23: 惠雅 | C23: 8.5 | G23: 年 | H23: 年 | J23: 8.5 | K23: 8.5 | R23: 8.5 | U23: 年 | V23: 年 | W23: 年 | Y23: 8.5 | AE23: 8.5 | AF23: 8.5 | AH23: {=-SUMPRODUCT((C23:AG23<>"年") * (C23:AG23<>"调") * (C23:AG23<>"病") * (C23:AG23<>"事") * C24:AG24)} -> 0 | AI23: =-(SUMIF(C23:AG23,"=年",C24:AG24)) -> 36 | AJ23: =-(SUMIF(C23:AG23,"=调",C24:AG24)) -> 0 | AK23: =-(SUMIF(C23:AG23,"=病",C24:AG24)) -> 0 | AL23: =-(SUMIF(C23:AG23,"=事",C24:AG24)) -> 0 | AM23: =SUMIF(C4:AG4,"P",C23:AG24) -> 0 | AN23: =SUMIF(C4:AG4,"S",C23:AG24) -> 59.5 | AO23: =SUMIF(C4:AG4,"G",C23:AG24) -> 0 | AP23: =AI23+'2026-07'!AP23 -> 49
G24: -4 | H24: -8 | U24: -8 | V24: -8 | W24: -8 | AM24: =IF(SUM(C23:AG23)-AJ23=0,"√",SUM(C23:AG23)-AJ23) -> 59.5
A25: 11 | B25: 张永妹 | C25: 8.5 | D25: 8.5 | J25: 8.5 | K25: 8.5 | R25: 8.5 | Y25: 8.5 | Z25: 年 | AE25: 8.5 | AF25: 8.5 | AH25: {=-SUMPRODUCT((C25:AG25<>"年") * (C25:AG25<>"调") * (C25:AG25<>"病") * (C25:AG25<>"事") * C26:AG26)} -> 0 | AI25: =-(SUMIF(C25:AG25,"=年",C26:AG26)) -> 1 | AJ25: =-(SUMIF(C25:AG25,"=调",C26:AG26)) -> 0 | AK25: =-(SUMIF(C25:AG25,"=病",C26:AG26)) -> 0 | AL25: =-(SUMIF(C25:AG25,"=事",C26:AG26)) -> 0 | AM25: =SUMIF(C4:AG4,"P",C25:AG26) -> 0 | AN25: =SUMIF(C4:AG4,"S",C25:AG26) -> 68 | AO25: =SUMIF(C4:AG4,"G",C25:AG26) -> 0 | AP25: =AI25+'2026-07'!AP25 -> 35
Z26: -1 | AM26: =IF(SUM(C25:AG25)-AJ25=0,"√",SUM(C25:AG25)-AJ25) -> 68
A27: 12 | B27: 亢亦宁 | W27: 年 | AC27: 年 | AH27: {=-SUMPRODUCT((C27:AG27<>"年") * (C27:AG27<>"调") * (C27:AG27<>"病") * (C27:AG27<>"事") * C28:AG28)} -> 0 | AI27: =-(SUMIF(C27:AG27,"=年",C28:AG28)) -> 10 | AJ27: =-(SUMIF(C27:AG27,"=调",C28:AG28)) -> 0 | AK27: =-(SUMIF(C27:AG27,"=病",C28:AG28)) -> 0 | AL27: =-(SUMIF(C27:AG27,"=事",C28:AG28)) -> 0 | AM27: =SUMIF(C4:AG4,"P",C27:AG28) -> 0 | AN27: =SUMIF(C4:AG4,"S",C27:AG28)-AJ27 -> 0 | AO27: =SUMIF(C4:AG4,"G",C27:AG28) -> 0 | AP27: =AI27+'2026-07'!AP27 -> 66.5
W28: -8 | AC28: -2 | AM28: =IF(SUM(C27:AG27)-AJ27=0,"√",SUM(C27:AG27)-AJ27) -> √
A29: 13 | B29: 赵婷 | AA29: 3 | AB29: 3 | AC29: 3 | AD29: 3 | AE29: 11.5 | AF29: 11.5 | AH29: {=-SUMPRODUCT((C29:AG29<>"年") * (C29:AG29<>"调") * (C29:AG29<>"病") * (C29:AG29<>"事") * C30:AG30)} -> 0 | AI29: =-(SUMIF(C29:AG29,"=年",C30:AG30)) -> 0 | AJ29: =-(SUMIF(C29:AG29,"=调",C30:AG30)) -> 0 | AK29: =-(SUMIF(C29:AG29,"=病",C30:AG30)) -> 0 | AL29: =-(SUMIF(C29:AG29,"=事",C30:AG30)) -> 0 | AM29: =SUMIF(C4:AG4,"P",C29:AG30) -> 12 | AN29: =SUMIF(C4:AG4,"S",C29:AG30)-AJ29 -> 23 | AO29: =SUMIF(C4:AG4,"G",C29:AG30) -> 0 | AP29: =AI29+'2026-07'!AP29 -> 0
AM30: =IF(SUM(C29:AG29)-AJ29=0,"√",SUM(C29:AG29)-AJ29) -> 35
A31: 注：①“年”-年假；“病”-有薪病假；“事”-事假；“独”-独生子女陪护假；“居”-居家办公 ②单位：小时；③调休优先抵扣优先级：双休日>国假>平时加班，调休后统计加班累计；
A32: 制表：（顾桢鸿） | S32: 审核：（马道旭） | AK32: 核准：

Sheet 2026-09
A1: 苏州晶讯科技股份有限公司 品管部
A2: 序号 | B2: 姓名 | C2: ="2026年9月出勤状况(工作日:"&COUNTIF(C4:AG4, "P")&"天)" -> 2026年9月出勤状况(工作日:22天) | AH2: 本月累计 | AP2: 年度 总计 年假 | AQ2: 备注
C3: 1 | D3: 2 | E3: 3 | F3: 4 | G3: 5 | H3: 6 | I3: 7 | J3: 8 | K3: 9 | L3: 10 | M3: 11 | N3: 12 | O3: 13 | P3: 14 | Q3: 15 | R3: 16 | S3: 17 | T3: 18 | U3: 19 | V3: 20 | W3: 21 | X3: 22 | Y3: 23 | Z3: 24 | AA3: 25 | AB3: 26 | AC3: 27 | AD3: 28 | AE3: 29 | AF3: 30 | AG3: 31 | AH3: 请假 | AM3: 加班
